2025-03-12 12:56:20,454 - INFO - Configuración de Supabase cargada correctamente
2025-03-12 12:56:21,013 - INFO - Cliente Supabase inicializado correctamente
2025-03-12 12:56:22,276 - ERROR - Error al cargar datos: Traceback (most recent call last):
  File "/home/lucasalvador/Reportes/CBAMECAPACITA/venv/lib/python3.12/site-packages/httpx/_transports/default.py", line 72, in map_httpcore_exceptions
    yield
  File "/home/lucasalvador/Reportes/CBAMECAPACITA/venv/lib/python3.12/site-packages/httpx/_transports/default.py", line 236, in handle_request
    resp = self._pool.handle_request(req)
           ^^^^^^^^^^^^^^^^^^^^^^^^^^^^^^
  File "/home/lucasalvador/Reportes/CBAMECAPACITA/venv/lib/python3.12/site-packages/httpcore/_sync/connection_pool.py", line 256, in handle_request
    raise exc from None
  File "/home/lucasalvador/Reportes/CBAMECAPACITA/venv/lib/python3.12/site-packages/httpcore/_sync/connection_pool.py", line 236, in handle_request
    response = connection.handle_request(
               ^^^^^^^^^^^^^^^^^^^^^^^^^^
  File "/home/lucasalvador/Reportes/CBAMECAPACITA/venv/lib/python3.12/site-packages/httpcore/_sync/connection.py", line 101, in handle_request
    raise exc
  File "/home/lucasalvador/Reportes/CBAMECAPACITA/venv/lib/python3.12/site-packages/httpcore/_sync/connection.py", line 78, in handle_request
    stream = self._connect(request)
             ^^^^^^^^^^^^^^^^^^^^^^
  File "/home/lucasalvador/Reportes/CBAMECAPACITA/venv/lib/python3.12/site-packages/httpcore/_sync/connection.py", line 124, in _connect
    stream = self._network_backend.connect_tcp(**kwargs)
             ^^^^^^^^^^^^^^^^^^^^^^^^^^^^^^^^^^^^^^^^^^^
  File "/home/lucasalvador/Reportes/CBAMECAPACITA/venv/lib/python3.12/site-packages/httpcore/_backends/sync.py", line 207, in connect_tcp
    with map_exceptions(exc_map):
  File "/usr/lib/python3.12/contextlib.py", line 158, in __exit__
    self.gen.throw(value)
  File "/home/lucasalvador/Reportes/CBAMECAPACITA/venv/lib/python3.12/site-packages/httpcore/_exceptions.py", line 14, in map_exceptions
    raise to_exc(exc) from exc
httpcore.ConnectError: [Errno -2] Name or service not known

The above exception was the direct cause of the following exception:

Traceback (most recent call last):
  File "/home/lucasalvador/Reportes/CBAMECAPACITA/venv/lib/python3.12/site-packages/storage3/_sync/file_api.py", line 46, in _request
    response = self._client.request(
               ^^^^^^^^^^^^^^^^^^^^^
  File "/home/lucasalvador/Reportes/CBAMECAPACITA/venv/lib/python3.12/site-packages/httpx/_client.py", line 837, in request
    return self.send(request, auth=auth, follow_redirects=follow_redirects)
           ^^^^^^^^^^^^^^^^^^^^^^^^^^^^^^^^^^^^^^^^^^^^^^^^^^^^^^^^^^^^^^^^
  File "/home/lucasalvador/Reportes/CBAMECAPACITA/venv/lib/python3.12/site-packages/httpx/_client.py", line 926, in send
    response = self._send_handling_auth(
               ^^^^^^^^^^^^^^^^^^^^^^^^^
  File "/home/lucasalvador/Reportes/CBAMECAPACITA/venv/lib/python3.12/site-packages/httpx/_client.py", line 954, in _send_handling_auth
    response = self._send_handling_redirects(
               ^^^^^^^^^^^^^^^^^^^^^^^^^^^^^^
  File "/home/lucasalvador/Reportes/CBAMECAPACITA/venv/lib/python3.12/site-packages/httpx/_client.py", line 991, in _send_handling_redirects
    response = self._send_single_request(request)
               ^^^^^^^^^^^^^^^^^^^^^^^^^^^^^^^^^^
  File "/home/lucasalvador/Reportes/CBAMECAPACITA/venv/lib/python3.12/site-packages/httpx/_client.py", line 1027, in _send_single_request
    response = transport.handle_request(request)
               ^^^^^^^^^^^^^^^^^^^^^^^^^^^^^^^^^
  File "/home/lucasalvador/Reportes/CBAMECAPACITA/venv/lib/python3.12/site-packages/httpx/_transports/default.py", line 235, in handle_request
    with map_httpcore_exceptions():
  File "/usr/lib/python3.12/contextlib.py", line 158, in __exit__
    self.gen.throw(value)
  File "/home/lucasalvador/Reportes/CBAMECAPACITA/venv/lib/python3.12/site-packages/httpx/_transports/default.py", line 89, in map_httpcore_exceptions
    raise mapped_exc(message) from exc
httpx.ConnectError: [Errno -2] Name or service not known

During handling of the above exception, another exception occurred:

Traceback (most recent call last):
  File "/home/lucasalvador/Reportes/CBAMECAPACITA/app.py", line 62, in cargar_datos_supabase
    respuesta = _supabase_client.storage.from_('CBAMECAPACITA').download('ALUMNOS_X_LOCALIDAD.parquet')
                ^^^^^^^^^^^^^^^^^^^^^^^^^^^^^^^^^^^^^^^^^^^^^^^^^^^^^^^^^^^^^^^^^^^^^^^^^^^^^^^^^^^^^^^
  File "/home/lucasalvador/Reportes/CBAMECAPACITA/venv/lib/python3.12/site-packages/storage3/_sync/file_api.py", line 363, in download
    response = self._request(
               ^^^^^^^^^^^^^^
  File "/home/lucasalvador/Reportes/CBAMECAPACITA/venv/lib/python3.12/site-packages/storage3/_sync/file_api.py", line 52, in _request
    resp = response.json()
           ^^^^^^^^
UnboundLocalError: cannot access local variable 'response' where it is not associated with a value

2025-03-12 13:04:30,280 - INFO - Configuración de Supabase cargada correctamente
2025-03-12 13:04:30,807 - INFO - Cliente Supabase inicializado correctamente
2025-03-12 13:04:32,045 - ERROR - Error al cargar datos: Traceback (most recent call last):
  File "/home/lucasalvador/Reportes/CBAMECAPACITA/venv/lib/python3.12/site-packages/httpx/_transports/default.py", line 72, in map_httpcore_exceptions
    yield
  File "/home/lucasalvador/Reportes/CBAMECAPACITA/venv/lib/python3.12/site-packages/httpx/_transports/default.py", line 236, in handle_request
    resp = self._pool.handle_request(req)
           ^^^^^^^^^^^^^^^^^^^^^^^^^^^^^^
  File "/home/lucasalvador/Reportes/CBAMECAPACITA/venv/lib/python3.12/site-packages/httpcore/_sync/connection_pool.py", line 256, in handle_request
    raise exc from None
  File "/home/lucasalvador/Reportes/CBAMECAPACITA/venv/lib/python3.12/site-packages/httpcore/_sync/connection_pool.py", line 236, in handle_request
    response = connection.handle_request(
               ^^^^^^^^^^^^^^^^^^^^^^^^^^
  File "/home/lucasalvador/Reportes/CBAMECAPACITA/venv/lib/python3.12/site-packages/httpcore/_sync/connection.py", line 101, in handle_request
    raise exc
  File "/home/lucasalvador/Reportes/CBAMECAPACITA/venv/lib/python3.12/site-packages/httpcore/_sync/connection.py", line 78, in handle_request
    stream = self._connect(request)
             ^^^^^^^^^^^^^^^^^^^^^^
  File "/home/lucasalvador/Reportes/CBAMECAPACITA/venv/lib/python3.12/site-packages/httpcore/_sync/connection.py", line 124, in _connect
    stream = self._network_backend.connect_tcp(**kwargs)
             ^^^^^^^^^^^^^^^^^^^^^^^^^^^^^^^^^^^^^^^^^^^
  File "/home/lucasalvador/Reportes/CBAMECAPACITA/venv/lib/python3.12/site-packages/httpcore/_backends/sync.py", line 207, in connect_tcp
    with map_exceptions(exc_map):
  File "/usr/lib/python3.12/contextlib.py", line 158, in __exit__
    self.gen.throw(value)
  File "/home/lucasalvador/Reportes/CBAMECAPACITA/venv/lib/python3.12/site-packages/httpcore/_exceptions.py", line 14, in map_exceptions
    raise to_exc(exc) from exc
httpcore.ConnectError: [Errno -2] Name or service not known

The above exception was the direct cause of the following exception:

Traceback (most recent call last):
  File "/home/lucasalvador/Reportes/CBAMECAPACITA/venv/lib/python3.12/site-packages/storage3/_sync/file_api.py", line 46, in _request
    response = self._client.request(
               ^^^^^^^^^^^^^^^^^^^^^
  File "/home/lucasalvador/Reportes/CBAMECAPACITA/venv/lib/python3.12/site-packages/httpx/_client.py", line 837, in request
    return self.send(request, auth=auth, follow_redirects=follow_redirects)
           ^^^^^^^^^^^^^^^^^^^^^^^^^^^^^^^^^^^^^^^^^^^^^^^^^^^^^^^^^^^^^^^^
  File "/home/lucasalvador/Reportes/CBAMECAPACITA/venv/lib/python3.12/site-packages/httpx/_client.py", line 926, in send
    response = self._send_handling_auth(
               ^^^^^^^^^^^^^^^^^^^^^^^^^
  File "/home/lucasalvador/Reportes/CBAMECAPACITA/venv/lib/python3.12/site-packages/httpx/_client.py", line 954, in _send_handling_auth
    response = self._send_handling_redirects(
               ^^^^^^^^^^^^^^^^^^^^^^^^^^^^^^
  File "/home/lucasalvador/Reportes/CBAMECAPACITA/venv/lib/python3.12/site-packages/httpx/_client.py", line 991, in _send_handling_redirects
    response = self._send_single_request(request)
               ^^^^^^^^^^^^^^^^^^^^^^^^^^^^^^^^^^
  File "/home/lucasalvador/Reportes/CBAMECAPACITA/venv/lib/python3.12/site-packages/httpx/_client.py", line 1027, in _send_single_request
    response = transport.handle_request(request)
               ^^^^^^^^^^^^^^^^^^^^^^^^^^^^^^^^^
  File "/home/lucasalvador/Reportes/CBAMECAPACITA/venv/lib/python3.12/site-packages/httpx/_transports/default.py", line 235, in handle_request
    with map_httpcore_exceptions():
  File "/usr/lib/python3.12/contextlib.py", line 158, in __exit__
    self.gen.throw(value)
  File "/home/lucasalvador/Reportes/CBAMECAPACITA/venv/lib/python3.12/site-packages/httpx/_transports/default.py", line 89, in map_httpcore_exceptions
    raise mapped_exc(message) from exc
httpx.ConnectError: [Errno -2] Name or service not known

During handling of the above exception, another exception occurred:

Traceback (most recent call last):
  File "/home/lucasalvador/Reportes/CBAMECAPACITA/app.py", line 62, in cargar_datos_supabase
    respuesta = _supabase_client.storage.from_('CBAMECAPACITA').download('ALUMNOS_X_LOCALIDAD.parquet')
                ^^^^^^^^^^^^^^^^^^^^^^^^^^^^^^^^^^^^^^^^^^^^^^^^^^^^^^^^^^^^^^^^^^^^^^^^^^^^^^^^^^^^^^^
  File "/home/lucasalvador/Reportes/CBAMECAPACITA/venv/lib/python3.12/site-packages/storage3/_sync/file_api.py", line 363, in download
    response = self._request(
               ^^^^^^^^^^^^^^
  File "/home/lucasalvador/Reportes/CBAMECAPACITA/venv/lib/python3.12/site-packages/storage3/_sync/file_api.py", line 52, in _request
    resp = response.json()
           ^^^^^^^^
UnboundLocalError: cannot access local variable 'response' where it is not associated with a value

2025-03-12 13:05:30,299 - INFO - Configuración de Supabase cargada correctamente
2025-03-12 13:05:30,833 - INFO - Cliente Supabase inicializado correctamente
2025-03-12 13:05:32,077 - ERROR - Error al cargar datos: Traceback (most recent call last):
  File "/home/lucasalvador/Reportes/CBAMECAPACITA/venv/lib/python3.12/site-packages/httpx/_transports/default.py", line 72, in map_httpcore_exceptions
    yield
  File "/home/lucasalvador/Reportes/CBAMECAPACITA/venv/lib/python3.12/site-packages/httpx/_transports/default.py", line 236, in handle_request
    resp = self._pool.handle_request(req)
           ^^^^^^^^^^^^^^^^^^^^^^^^^^^^^^
  File "/home/lucasalvador/Reportes/CBAMECAPACITA/venv/lib/python3.12/site-packages/httpcore/_sync/connection_pool.py", line 256, in handle_request
    raise exc from None
  File "/home/lucasalvador/Reportes/CBAMECAPACITA/venv/lib/python3.12/site-packages/httpcore/_sync/connection_pool.py", line 236, in handle_request
    response = connection.handle_request(
               ^^^^^^^^^^^^^^^^^^^^^^^^^^
  File "/home/lucasalvador/Reportes/CBAMECAPACITA/venv/lib/python3.12/site-packages/httpcore/_sync/connection.py", line 101, in handle_request
    raise exc
  File "/home/lucasalvador/Reportes/CBAMECAPACITA/venv/lib/python3.12/site-packages/httpcore/_sync/connection.py", line 78, in handle_request
    stream = self._connect(request)
             ^^^^^^^^^^^^^^^^^^^^^^
  File "/home/lucasalvador/Reportes/CBAMECAPACITA/venv/lib/python3.12/site-packages/httpcore/_sync/connection.py", line 124, in _connect
    stream = self._network_backend.connect_tcp(**kwargs)
             ^^^^^^^^^^^^^^^^^^^^^^^^^^^^^^^^^^^^^^^^^^^
  File "/home/lucasalvador/Reportes/CBAMECAPACITA/venv/lib/python3.12/site-packages/httpcore/_backends/sync.py", line 207, in connect_tcp
    with map_exceptions(exc_map):
  File "/usr/lib/python3.12/contextlib.py", line 158, in __exit__
    self.gen.throw(value)
  File "/home/lucasalvador/Reportes/CBAMECAPACITA/venv/lib/python3.12/site-packages/httpcore/_exceptions.py", line 14, in map_exceptions
    raise to_exc(exc) from exc
httpcore.ConnectError: [Errno -2] Name or service not known

The above exception was the direct cause of the following exception:

Traceback (most recent call last):
  File "/home/lucasalvador/Reportes/CBAMECAPACITA/venv/lib/python3.12/site-packages/storage3/_sync/file_api.py", line 46, in _request
    response = self._client.request(
               ^^^^^^^^^^^^^^^^^^^^^
  File "/home/lucasalvador/Reportes/CBAMECAPACITA/venv/lib/python3.12/site-packages/httpx/_client.py", line 837, in request
    return self.send(request, auth=auth, follow_redirects=follow_redirects)
           ^^^^^^^^^^^^^^^^^^^^^^^^^^^^^^^^^^^^^^^^^^^^^^^^^^^^^^^^^^^^^^^^
  File "/home/lucasalvador/Reportes/CBAMECAPACITA/venv/lib/python3.12/site-packages/httpx/_client.py", line 926, in send
    response = self._send_handling_auth(
               ^^^^^^^^^^^^^^^^^^^^^^^^^
  File "/home/lucasalvador/Reportes/CBAMECAPACITA/venv/lib/python3.12/site-packages/httpx/_client.py", line 954, in _send_handling_auth
    response = self._send_handling_redirects(
               ^^^^^^^^^^^^^^^^^^^^^^^^^^^^^^
  File "/home/lucasalvador/Reportes/CBAMECAPACITA/venv/lib/python3.12/site-packages/httpx/_client.py", line 991, in _send_handling_redirects
    response = self._send_single_request(request)
               ^^^^^^^^^^^^^^^^^^^^^^^^^^^^^^^^^^
  File "/home/lucasalvador/Reportes/CBAMECAPACITA/venv/lib/python3.12/site-packages/httpx/_client.py", line 1027, in _send_single_request
    response = transport.handle_request(request)
               ^^^^^^^^^^^^^^^^^^^^^^^^^^^^^^^^^
  File "/home/lucasalvador/Reportes/CBAMECAPACITA/venv/lib/python3.12/site-packages/httpx/_transports/default.py", line 235, in handle_request
    with map_httpcore_exceptions():
  File "/usr/lib/python3.12/contextlib.py", line 158, in __exit__
    self.gen.throw(value)
  File "/home/lucasalvador/Reportes/CBAMECAPACITA/venv/lib/python3.12/site-packages/httpx/_transports/default.py", line 89, in map_httpcore_exceptions
    raise mapped_exc(message) from exc
httpx.ConnectError: [Errno -2] Name or service not known

During handling of the above exception, another exception occurred:

Traceback (most recent call last):
  File "/home/lucasalvador/Reportes/CBAMECAPACITA/app.py", line 62, in cargar_datos_supabase
    respuesta = _supabase_client.storage.from_('CBAMECAPACITA').download('ALUMNOS_X_LOCALIDAD.parquet')
                ^^^^^^^^^^^^^^^^^^^^^^^^^^^^^^^^^^^^^^^^^^^^^^^^^^^^^^^^^^^^^^^^^^^^^^^^^^^^^^^^^^^^^^^
  File "/home/lucasalvador/Reportes/CBAMECAPACITA/venv/lib/python3.12/site-packages/storage3/_sync/file_api.py", line 363, in download
    response = self._request(
               ^^^^^^^^^^^^^^
  File "/home/lucasalvador/Reportes/CBAMECAPACITA/venv/lib/python3.12/site-packages/storage3/_sync/file_api.py", line 52, in _request
    resp = response.json()
           ^^^^^^^^
UnboundLocalError: cannot access local variable 'response' where it is not associated with a value

2025-04-01 15:07:31,059 - INFO - Configuración de Supabase cargada correctamente
2025-04-01 15:07:31,665 - INFO - Cliente Supabase inicializado correctamente
2025-04-01 15:07:32,875 - ERROR - Error al cargar datos: Traceback (most recent call last):
  File "/home/lucasalvador/Reportes/CBAMECAPACITA/venv/lib/python3.12/site-packages/httpx/_transports/default.py", line 72, in map_httpcore_exceptions
    yield
  File "/home/lucasalvador/Reportes/CBAMECAPACITA/venv/lib/python3.12/site-packages/httpx/_transports/default.py", line 236, in handle_request
    resp = self._pool.handle_request(req)
           ^^^^^^^^^^^^^^^^^^^^^^^^^^^^^^
  File "/home/lucasalvador/Reportes/CBAMECAPACITA/venv/lib/python3.12/site-packages/httpcore/_sync/connection_pool.py", line 256, in handle_request
    raise exc from None
  File "/home/lucasalvador/Reportes/CBAMECAPACITA/venv/lib/python3.12/site-packages/httpcore/_sync/connection_pool.py", line 236, in handle_request
    response = connection.handle_request(
               ^^^^^^^^^^^^^^^^^^^^^^^^^^
  File "/home/lucasalvador/Reportes/CBAMECAPACITA/venv/lib/python3.12/site-packages/httpcore/_sync/connection.py", line 101, in handle_request
    raise exc
  File "/home/lucasalvador/Reportes/CBAMECAPACITA/venv/lib/python3.12/site-packages/httpcore/_sync/connection.py", line 78, in handle_request
    stream = self._connect(request)
             ^^^^^^^^^^^^^^^^^^^^^^
  File "/home/lucasalvador/Reportes/CBAMECAPACITA/venv/lib/python3.12/site-packages/httpcore/_sync/connection.py", line 124, in _connect
    stream = self._network_backend.connect_tcp(**kwargs)
             ^^^^^^^^^^^^^^^^^^^^^^^^^^^^^^^^^^^^^^^^^^^
  File "/home/lucasalvador/Reportes/CBAMECAPACITA/venv/lib/python3.12/site-packages/httpcore/_backends/sync.py", line 207, in connect_tcp
    with map_exceptions(exc_map):
  File "/usr/lib/python3.12/contextlib.py", line 158, in __exit__
    self.gen.throw(value)
  File "/home/lucasalvador/Reportes/CBAMECAPACITA/venv/lib/python3.12/site-packages/httpcore/_exceptions.py", line 14, in map_exceptions
    raise to_exc(exc) from exc
httpcore.ConnectError: [Errno -2] Name or service not known

The above exception was the direct cause of the following exception:

Traceback (most recent call last):
  File "/home/lucasalvador/Reportes/CBAMECAPACITA/venv/lib/python3.12/site-packages/storage3/_sync/file_api.py", line 46, in _request
    response = self._client.request(
               ^^^^^^^^^^^^^^^^^^^^^
  File "/home/lucasalvador/Reportes/CBAMECAPACITA/venv/lib/python3.12/site-packages/httpx/_client.py", line 837, in request
    return self.send(request, auth=auth, follow_redirects=follow_redirects)
           ^^^^^^^^^^^^^^^^^^^^^^^^^^^^^^^^^^^^^^^^^^^^^^^^^^^^^^^^^^^^^^^^
  File "/home/lucasalvador/Reportes/CBAMECAPACITA/venv/lib/python3.12/site-packages/httpx/_client.py", line 926, in send
    response = self._send_handling_auth(
               ^^^^^^^^^^^^^^^^^^^^^^^^^
  File "/home/lucasalvador/Reportes/CBAMECAPACITA/venv/lib/python3.12/site-packages/httpx/_client.py", line 954, in _send_handling_auth
    response = self._send_handling_redirects(
               ^^^^^^^^^^^^^^^^^^^^^^^^^^^^^^
  File "/home/lucasalvador/Reportes/CBAMECAPACITA/venv/lib/python3.12/site-packages/httpx/_client.py", line 991, in _send_handling_redirects
    response = self._send_single_request(request)
               ^^^^^^^^^^^^^^^^^^^^^^^^^^^^^^^^^^
  File "/home/lucasalvador/Reportes/CBAMECAPACITA/venv/lib/python3.12/site-packages/httpx/_client.py", line 1027, in _send_single_request
    response = transport.handle_request(request)
               ^^^^^^^^^^^^^^^^^^^^^^^^^^^^^^^^^
  File "/home/lucasalvador/Reportes/CBAMECAPACITA/venv/lib/python3.12/site-packages/httpx/_transports/default.py", line 235, in handle_request
    with map_httpcore_exceptions():
  File "/usr/lib/python3.12/contextlib.py", line 158, in __exit__
    self.gen.throw(value)
  File "/home/lucasalvador/Reportes/CBAMECAPACITA/venv/lib/python3.12/site-packages/httpx/_transports/default.py", line 89, in map_httpcore_exceptions
    raise mapped_exc(message) from exc
httpx.ConnectError: [Errno -2] Name or service not known

During handling of the above exception, another exception occurred:

Traceback (most recent call last):
  File "/home/lucasalvador/Reportes/CBAMECAPACITA/app.py", line 62, in cargar_datos_supabase
    respuesta = _supabase_client.storage.from_('CBAMECAPACITA').download('ALUMNOS_X_LOCALIDAD.parquet')
                ^^^^^^^^^^^^^^^^^^^^^^^^^^^^^^^^^^^^^^^^^^^^^^^^^^^^^^^^^^^^^^^^^^^^^^^^^^^^^^^^^^^^^^^
  File "/home/lucasalvador/Reportes/CBAMECAPACITA/venv/lib/python3.12/site-packages/storage3/_sync/file_api.py", line 363, in download
    response = self._request(
               ^^^^^^^^^^^^^^
  File "/home/lucasalvador/Reportes/CBAMECAPACITA/venv/lib/python3.12/site-packages/storage3/_sync/file_api.py", line 52, in _request
    resp = response.json()
           ^^^^^^^^
UnboundLocalError: cannot access local variable 'response' where it is not associated with a value

2025-04-01 15:16:36,084 - INFO - Configuración de Hugging Face cargada correctamente
2025-04-01 15:16:36,087 - INFO - Descargando archivo desde Hugging Face: Dir-Tecno/CBAMECAPACITA
2025-04-01 15:16:41,291 - INFO - Datos cargados exitosamente: 251288 registros
2025-04-01 15:20:46,067 - INFO - Configuración de Hugging Face cargada correctamente
2025-04-01 15:20:54,042 - INFO - Configuración de Hugging Face cargada correctamente
2025-04-01 15:20:55,287 - INFO - Configuración de Hugging Face cargada correctamente
2025-04-01 15:21:04,032 - INFO - Configuración de Hugging Face cargada correctamente
2025-04-01 15:21:05,177 - INFO - Configuración de Hugging Face cargada correctamente
2025-04-01 15:24:24,334 - INFO - Configuración de Hugging Face cargada correctamente
2025-04-01 15:24:24,337 - INFO - Descargando archivo desde Hugging Face: Dir-Tecno/CBAMECAPACITA
2025-04-01 15:24:36,182 - INFO - Datos cargados exitosamente: 251288 registros
2025-04-24 20:36:36,397 - INFO - Configuración de Hugging Face cargada correctamente
2025-04-24 20:36:36,402 - INFO - Descargando archivo desde Hugging Face: Dir-Tecno/CBAMECAPACITA
2025-04-24 20:36:38,649 - INFO - Datos cargados exitosamente: 251288 registros
2025-04-24 20:36:43,720 - INFO - Configuración de Hugging Face cargada correctamente
