2025-04-28 12:54:22,012 - INFO - Configuraci√≥n de Hugging Face cargada correctamente
2025-04-28 12:54:22,017 - INFO - Descargando archivo desde Hugging Face: Dir-Tecno/CBAMECAPACITA
2025-04-28 12:54:24,191 - INFO - Datos cargados exitosamente: 251288 registros
2025-04-28 12:54:26,009 - ERROR - Error al cargar datos: Traceback (most recent call last):
  File "/home/lucasalvador/Reportes/CBAMECAPACITA/venv/lib/python3.12/site-packages/sqlalchemy/engine/base.py", line 146, in __init__
    self._dbapi_connection = engine.raw_connection()
                             ^^^^^^^^^^^^^^^^^^^^^^^
  File "/home/lucasalvador/Reportes/CBAMECAPACITA/venv/lib/python3.12/site-packages/sqlalchemy/engine/base.py", line 3298, in raw_connection
    return self.pool.connect()
           ^^^^^^^^^^^^^^^^^^^
  File "/home/lucasalvador/Reportes/CBAMECAPACITA/venv/lib/python3.12/site-packages/sqlalchemy/pool/base.py", line 449, in connect
    return _ConnectionFairy._checkout(self)
           ^^^^^^^^^^^^^^^^^^^^^^^^^^^^^^^^
  File "/home/lucasalvador/Reportes/CBAMECAPACITA/venv/lib/python3.12/site-packages/sqlalchemy/pool/base.py", line 1264, in _checkout
    fairy = _ConnectionRecord.checkout(pool)
            ^^^^^^^^^^^^^^^^^^^^^^^^^^^^^^^^
  File "/home/lucasalvador/Reportes/CBAMECAPACITA/venv/lib/python3.12/site-packages/sqlalchemy/pool/base.py", line 713, in checkout
    rec = pool._do_get()
          ^^^^^^^^^^^^^^
  File "/home/lucasalvador/Reportes/CBAMECAPACITA/venv/lib/python3.12/site-packages/sqlalchemy/pool/impl.py", line 179, in _do_get
    with util.safe_reraise():
  File "/home/lucasalvador/Reportes/CBAMECAPACITA/venv/lib/python3.12/site-packages/sqlalchemy/util/langhelpers.py", line 146, in __exit__
    raise exc_value.with_traceback(exc_tb)
  File "/home/lucasalvador/Reportes/CBAMECAPACITA/venv/lib/python3.12/site-packages/sqlalchemy/pool/impl.py", line 177, in _do_get
    return self._create_connection()
           ^^^^^^^^^^^^^^^^^^^^^^^^^
  File "/home/lucasalvador/Reportes/CBAMECAPACITA/venv/lib/python3.12/site-packages/sqlalchemy/pool/base.py", line 390, in _create_connection
    return _ConnectionRecord(self)
           ^^^^^^^^^^^^^^^^^^^^^^^
  File "/home/lucasalvador/Reportes/CBAMECAPACITA/venv/lib/python3.12/site-packages/sqlalchemy/pool/base.py", line 675, in __init__
    self.__connect()
  File "/home/lucasalvador/Reportes/CBAMECAPACITA/venv/lib/python3.12/site-packages/sqlalchemy/pool/base.py", line 901, in __connect
    with util.safe_reraise():
  File "/home/lucasalvador/Reportes/CBAMECAPACITA/venv/lib/python3.12/site-packages/sqlalchemy/util/langhelpers.py", line 146, in __exit__
    raise exc_value.with_traceback(exc_tb)
  File "/home/lucasalvador/Reportes/CBAMECAPACITA/venv/lib/python3.12/site-packages/sqlalchemy/pool/base.py", line 897, in __connect
    self.dbapi_connection = connection = pool._invoke_creator(self)
                                         ^^^^^^^^^^^^^^^^^^^^^^^^^^
  File "/home/lucasalvador/Reportes/CBAMECAPACITA/venv/lib/python3.12/site-packages/sqlalchemy/engine/create.py", line 646, in connect
    return dialect.connect(*cargs, **cparams)
           ^^^^^^^^^^^^^^^^^^^^^^^^^^^^^^^^^^
  File "/home/lucasalvador/Reportes/CBAMECAPACITA/venv/lib/python3.12/site-packages/sqlalchemy/engine/default.py", line 625, in connect
    return self.loaded_dbapi.connect(*cargs, **cparams)  # type: ignore[no-any-return]  # NOQA: E501
           ^^^^^^^^^^^^^^^^^^^^^^^^^^^^^^^^^^^^^^^^^^^^
  File "/home/lucasalvador/Reportes/CBAMECAPACITA/venv/lib/python3.12/site-packages/pymysql/connections.py", line 361, in __init__
    self.connect()
  File "/home/lucasalvador/Reportes/CBAMECAPACITA/venv/lib/python3.12/site-packages/pymysql/connections.py", line 669, in connect
    self._request_authentication()
  File "/home/lucasalvador/Reportes/CBAMECAPACITA/venv/lib/python3.12/site-packages/pymysql/connections.py", line 957, in _request_authentication
    auth_packet = self._read_packet()
                  ^^^^^^^^^^^^^^^^^^^
  File "/home/lucasalvador/Reportes/CBAMECAPACITA/venv/lib/python3.12/site-packages/pymysql/connections.py", line 775, in _read_packet
    packet.raise_for_error()
  File "/home/lucasalvador/Reportes/CBAMECAPACITA/venv/lib/python3.12/site-packages/pymysql/protocol.py", line 219, in raise_for_error
    err.raise_mysql_exception(self._data)
  File "/home/lucasalvador/Reportes/CBAMECAPACITA/venv/lib/python3.12/site-packages/pymysql/err.py", line 150, in raise_mysql_exception
    raise errorclass(errno, errval)
pymysql.err.OperationalError: (1049, "Unknown database 'netznet'")

The above exception was the direct cause of the following exception:

Traceback (most recent call last):
  File "/home/lucasalvador/Reportes/CBAMECAPACITA/src/pages/comparar_cursos.py", line 40, in load_data
    df_historico = pd.read_sql(query_historico, engine)
                   ^^^^^^^^^^^^^^^^^^^^^^^^^^^^^^^^^^^^
  File "/home/lucasalvador/Reportes/CBAMECAPACITA/venv/lib/python3.12/site-packages/pandas/io/sql.py", line 704, in read_sql
    with pandasSQL_builder(con) as pandas_sql:
         ^^^^^^^^^^^^^^^^^^^^^^
  File "/home/lucasalvador/Reportes/CBAMECAPACITA/venv/lib/python3.12/site-packages/pandas/io/sql.py", line 906, in pandasSQL_builder
    return SQLDatabase(con, schema, need_transaction)
           ^^^^^^^^^^^^^^^^^^^^^^^^^^^^^^^^^^^^^^^^^^
  File "/home/lucasalvador/Reportes/CBAMECAPACITA/venv/lib/python3.12/site-packages/pandas/io/sql.py", line 1636, in __init__
    con = self.exit_stack.enter_context(con.connect())
                                        ^^^^^^^^^^^^^
  File "/home/lucasalvador/Reportes/CBAMECAPACITA/venv/lib/python3.12/site-packages/sqlalchemy/engine/base.py", line 3274, in connect
    return self._connection_cls(self)
           ^^^^^^^^^^^^^^^^^^^^^^^^^^
  File "/home/lucasalvador/Reportes/CBAMECAPACITA/venv/lib/python3.12/site-packages/sqlalchemy/engine/base.py", line 148, in __init__
    Connection._handle_dbapi_exception_noconnection(
  File "/home/lucasalvador/Reportes/CBAMECAPACITA/venv/lib/python3.12/site-packages/sqlalchemy/engine/base.py", line 2439, in _handle_dbapi_exception_noconnection
    raise sqlalchemy_exception.with_traceback(exc_info[2]) from e
  File "/home/lucasalvador/Reportes/CBAMECAPACITA/venv/lib/python3.12/site-packages/sqlalchemy/engine/base.py", line 146, in __init__
    self._dbapi_connection = engine.raw_connection()
                             ^^^^^^^^^^^^^^^^^^^^^^^
  File "/home/lucasalvador/Reportes/CBAMECAPACITA/venv/lib/python3.12/site-packages/sqlalchemy/engine/base.py", line 3298, in raw_connection
    return self.pool.connect()
           ^^^^^^^^^^^^^^^^^^^
  File "/home/lucasalvador/Reportes/CBAMECAPACITA/venv/lib/python3.12/site-packages/sqlalchemy/pool/base.py", line 449, in connect
    return _ConnectionFairy._checkout(self)
           ^^^^^^^^^^^^^^^^^^^^^^^^^^^^^^^^
  File "/home/lucasalvador/Reportes/CBAMECAPACITA/venv/lib/python3.12/site-packages/sqlalchemy/pool/base.py", line 1264, in _checkout
    fairy = _ConnectionRecord.checkout(pool)
            ^^^^^^^^^^^^^^^^^^^^^^^^^^^^^^^^
  File "/home/lucasalvador/Reportes/CBAMECAPACITA/venv/lib/python3.12/site-packages/sqlalchemy/pool/base.py", line 713, in checkout
    rec = pool._do_get()
          ^^^^^^^^^^^^^^
  File "/home/lucasalvador/Reportes/CBAMECAPACITA/venv/lib/python3.12/site-packages/sqlalchemy/pool/impl.py", line 179, in _do_get
    with util.safe_reraise():
  File "/home/lucasalvador/Reportes/CBAMECAPACITA/venv/lib/python3.12/site-packages/sqlalchemy/util/langhelpers.py", line 146, in __exit__
    raise exc_value.with_traceback(exc_tb)
  File "/home/lucasalvador/Reportes/CBAMECAPACITA/venv/lib/python3.12/site-packages/sqlalchemy/pool/impl.py", line 177, in _do_get
    return self._create_connection()
           ^^^^^^^^^^^^^^^^^^^^^^^^^
  File "/home/lucasalvador/Reportes/CBAMECAPACITA/venv/lib/python3.12/site-packages/sqlalchemy/pool/base.py", line 390, in _create_connection
    return _ConnectionRecord(self)
           ^^^^^^^^^^^^^^^^^^^^^^^
  File "/home/lucasalvador/Reportes/CBAMECAPACITA/venv/lib/python3.12/site-packages/sqlalchemy/pool/base.py", line 675, in __init__
    self.__connect()
  File "/home/lucasalvador/Reportes/CBAMECAPACITA/venv/lib/python3.12/site-packages/sqlalchemy/pool/base.py", line 901, in __connect
    with util.safe_reraise():
  File "/home/lucasalvador/Reportes/CBAMECAPACITA/venv/lib/python3.12/site-packages/sqlalchemy/util/langhelpers.py", line 146, in __exit__
    raise exc_value.with_traceback(exc_tb)
  File "/home/lucasalvador/Reportes/CBAMECAPACITA/venv/lib/python3.12/site-packages/sqlalchemy/pool/base.py", line 897, in __connect
    self.dbapi_connection = connection = pool._invoke_creator(self)
                                         ^^^^^^^^^^^^^^^^^^^^^^^^^^
  File "/home/lucasalvador/Reportes/CBAMECAPACITA/venv/lib/python3.12/site-packages/sqlalchemy/engine/create.py", line 646, in connect
    return dialect.connect(*cargs, **cparams)
           ^^^^^^^^^^^^^^^^^^^^^^^^^^^^^^^^^^
  File "/home/lucasalvador/Reportes/CBAMECAPACITA/venv/lib/python3.12/site-packages/sqlalchemy/engine/default.py", line 625, in connect
    return self.loaded_dbapi.connect(*cargs, **cparams)  # type: ignore[no-any-return]  # NOQA: E501
           ^^^^^^^^^^^^^^^^^^^^^^^^^^^^^^^^^^^^^^^^^^^^
  File "/home/lucasalvador/Reportes/CBAMECAPACITA/venv/lib/python3.12/site-packages/pymysql/connections.py", line 361, in __init__
    self.connect()
  File "/home/lucasalvador/Reportes/CBAMECAPACITA/venv/lib/python3.12/site-packages/pymysql/connections.py", line 669, in connect
    self._request_authentication()
  File "/home/lucasalvador/Reportes/CBAMECAPACITA/venv/lib/python3.12/site-packages/pymysql/connections.py", line 957, in _request_authentication
    auth_packet = self._read_packet()
                  ^^^^^^^^^^^^^^^^^^^
  File "/home/lucasalvador/Reportes/CBAMECAPACITA/venv/lib/python3.12/site-packages/pymysql/connections.py", line 775, in _read_packet
    packet.raise_for_error()
  File "/home/lucasalvador/Reportes/CBAMECAPACITA/venv/lib/python3.12/site-packages/pymysql/protocol.py", line 219, in raise_for_error
    err.raise_mysql_exception(self._data)
  File "/home/lucasalvador/Reportes/CBAMECAPACITA/venv/lib/python3.12/site-packages/pymysql/err.py", line 150, in raise_mysql_exception
    raise errorclass(errno, errval)
sqlalchemy.exc.OperationalError: (pymysql.err.OperationalError) (1049, "Unknown database 'netznet'")
(Background on this error at: https://sqlalche.me/e/20/e3q8)

2025-04-28 12:56:09,336 - INFO - Configuraci√≥n de Hugging Face cargada correctamente
2025-04-28 12:56:12,960 - ERROR - Error al cargar datos: Traceback (most recent call last):
  File "/home/lucasalvador/Reportes/CBAMECAPACITA/venv/lib/python3.12/site-packages/sqlalchemy/engine/base.py", line 1964, in _exec_single_context
    self.dialect.do_execute(
  File "/home/lucasalvador/Reportes/CBAMECAPACITA/venv/lib/python3.12/site-packages/sqlalchemy/engine/default.py", line 945, in do_execute
    cursor.execute(statement, parameters)
  File "/home/lucasalvador/Reportes/CBAMECAPACITA/venv/lib/python3.12/site-packages/pymysql/cursors.py", line 153, in execute
    result = self._query(query)
             ^^^^^^^^^^^^^^^^^^
  File "/home/lucasalvador/Reportes/CBAMECAPACITA/venv/lib/python3.12/site-packages/pymysql/cursors.py", line 322, in _query
    conn.query(q)
  File "/home/lucasalvador/Reportes/CBAMECAPACITA/venv/lib/python3.12/site-packages/pymysql/connections.py", line 563, in query
    self._affected_rows = self._read_query_result(unbuffered=unbuffered)
                          ^^^^^^^^^^^^^^^^^^^^^^^^^^^^^^^^^^^^^^^^^^^^^^
  File "/home/lucasalvador/Reportes/CBAMECAPACITA/venv/lib/python3.12/site-packages/pymysql/connections.py", line 825, in _read_query_result
    result.read()
  File "/home/lucasalvador/Reportes/CBAMECAPACITA/venv/lib/python3.12/site-packages/pymysql/connections.py", line 1199, in read
    first_packet = self.connection._read_packet()
                   ^^^^^^^^^^^^^^^^^^^^^^^^^^^^^^
  File "/home/lucasalvador/Reportes/CBAMECAPACITA/venv/lib/python3.12/site-packages/pymysql/connections.py", line 775, in _read_packet
    packet.raise_for_error()
  File "/home/lucasalvador/Reportes/CBAMECAPACITA/venv/lib/python3.12/site-packages/pymysql/protocol.py", line 219, in raise_for_error
    err.raise_mysql_exception(self._data)
  File "/home/lucasalvador/Reportes/CBAMECAPACITA/venv/lib/python3.12/site-packages/pymysql/err.py", line 150, in raise_mysql_exception
    raise errorclass(errno, errval)
pymysql.err.ProgrammingError: (1146, "Table 'CBAMECAPACITA.T_CURSOS_HISTORICOS' doesn't exist")

The above exception was the direct cause of the following exception:

Traceback (most recent call last):
  File "/home/lucasalvador/Reportes/CBAMECAPACITA/src/pages/comparar_cursos.py", line 40, in load_data
    df_historico = pd.read_sql(query_historico, engine)
                   ^^^^^^^^^^^^^^^^^^^^^^^^^^^^^^^^^^^^
  File "/home/lucasalvador/Reportes/CBAMECAPACITA/venv/lib/python3.12/site-packages/pandas/io/sql.py", line 734, in read_sql
    return pandas_sql.read_query(
           ^^^^^^^^^^^^^^^^^^^^^^
  File "/home/lucasalvador/Reportes/CBAMECAPACITA/venv/lib/python3.12/site-packages/pandas/io/sql.py", line 1836, in read_query
    result = self.execute(sql, params)
             ^^^^^^^^^^^^^^^^^^^^^^^^^
  File "/home/lucasalvador/Reportes/CBAMECAPACITA/venv/lib/python3.12/site-packages/pandas/io/sql.py", line 1659, in execute
    return self.con.exec_driver_sql(sql, *args)
           ^^^^^^^^^^^^^^^^^^^^^^^^^^^^^^^^^^^^
  File "/home/lucasalvador/Reportes/CBAMECAPACITA/venv/lib/python3.12/site-packages/sqlalchemy/engine/base.py", line 1776, in exec_driver_sql
    ret = self._execute_context(
          ^^^^^^^^^^^^^^^^^^^^^^
  File "/home/lucasalvador/Reportes/CBAMECAPACITA/venv/lib/python3.12/site-packages/sqlalchemy/engine/base.py", line 1843, in _execute_context
    return self._exec_single_context(
           ^^^^^^^^^^^^^^^^^^^^^^^^^^
  File "/home/lucasalvador/Reportes/CBAMECAPACITA/venv/lib/python3.12/site-packages/sqlalchemy/engine/base.py", line 1983, in _exec_single_context
    self._handle_dbapi_exception(
  File "/home/lucasalvador/Reportes/CBAMECAPACITA/venv/lib/python3.12/site-packages/sqlalchemy/engine/base.py", line 2352, in _handle_dbapi_exception
    raise sqlalchemy_exception.with_traceback(exc_info[2]) from e
  File "/home/lucasalvador/Reportes/CBAMECAPACITA/venv/lib/python3.12/site-packages/sqlalchemy/engine/base.py", line 1964, in _exec_single_context
    self.dialect.do_execute(
  File "/home/lucasalvador/Reportes/CBAMECAPACITA/venv/lib/python3.12/site-packages/sqlalchemy/engine/default.py", line 945, in do_execute
    cursor.execute(statement, parameters)
  File "/home/lucasalvador/Reportes/CBAMECAPACITA/venv/lib/python3.12/site-packages/pymysql/cursors.py", line 153, in execute
    result = self._query(query)
             ^^^^^^^^^^^^^^^^^^
  File "/home/lucasalvador/Reportes/CBAMECAPACITA/venv/lib/python3.12/site-packages/pymysql/cursors.py", line 322, in _query
    conn.query(q)
  File "/home/lucasalvador/Reportes/CBAMECAPACITA/venv/lib/python3.12/site-packages/pymysql/connections.py", line 563, in query
    self._affected_rows = self._read_query_result(unbuffered=unbuffered)
                          ^^^^^^^^^^^^^^^^^^^^^^^^^^^^^^^^^^^^^^^^^^^^^^
  File "/home/lucasalvador/Reportes/CBAMECAPACITA/venv/lib/python3.12/site-packages/pymysql/connections.py", line 825, in _read_query_result
    result.read()
  File "/home/lucasalvador/Reportes/CBAMECAPACITA/venv/lib/python3.12/site-packages/pymysql/connections.py", line 1199, in read
    first_packet = self.connection._read_packet()
                   ^^^^^^^^^^^^^^^^^^^^^^^^^^^^^^
  File "/home/lucasalvador/Reportes/CBAMECAPACITA/venv/lib/python3.12/site-packages/pymysql/connections.py", line 775, in _read_packet
    packet.raise_for_error()
  File "/home/lucasalvador/Reportes/CBAMECAPACITA/venv/lib/python3.12/site-packages/pymysql/protocol.py", line 219, in raise_for_error
    err.raise_mysql_exception(self._data)
  File "/home/lucasalvador/Reportes/CBAMECAPACITA/venv/lib/python3.12/site-packages/pymysql/err.py", line 150, in raise_mysql_exception
    raise errorclass(errno, errval)
sqlalchemy.exc.ProgrammingError: (pymysql.err.ProgrammingError) (1146, "Table 'CBAMECAPACITA.T_CURSOS_HISTORICOS' doesn't exist")
[SQL: SELECT * FROM T_CURSOS_HISTORICOS]
(Background on this error at: https://sqlalche.me/e/20/f405)

2025-04-28 12:57:50,087 - INFO - Configuraci√≥n de Hugging Face cargada correctamente
2025-04-28 13:04:18,065 - INFO - Configuraci√≥n de Hugging Face cargada correctamente
2025-04-28 13:05:11,599 - ERROR - Error en an√°lisis de compatibilidad: Traceback (most recent call last):
  File "/home/lucasalvador/Reportes/CBAMECAPACITA/venv/lib/python3.12/site-packages/pandas/core/indexes/base.py", line 3805, in get_loc
    return self._engine.get_loc(casted_key)
           ^^^^^^^^^^^^^^^^^^^^^^^^^^^^^^^^
  File "index.pyx", line 167, in pandas._libs.index.IndexEngine.get_loc
  File "index.pyx", line 196, in pandas._libs.index.IndexEngine.get_loc
  File "pandas/_libs/hashtable_class_helper.pxi", line 7081, in pandas._libs.hashtable.PyObjectHashTable.get_item
  File "pandas/_libs/hashtable_class_helper.pxi", line 7089, in pandas._libs.hashtable.PyObjectHashTable.get_item
KeyError: 'id_certificacion'

The above exception was the direct cause of the following exception:

Traceback (most recent call last):
  File "/home/lucasalvador/Reportes/CBAMECAPACITA/src/pages/comparar_cursos.py", line 109, in analizar_compatibilidad
    df_certificaciones['id_certificacion'].unique(),
    ~~~~~~~~~~~~~~~~~~^^^^^^^^^^^^^^^^^^^^
  File "/home/lucasalvador/Reportes/CBAMECAPACITA/venv/lib/python3.12/site-packages/pandas/core/frame.py", line 4102, in __getitem__
    indexer = self.columns.get_loc(key)
              ^^^^^^^^^^^^^^^^^^^^^^^^^
  File "/home/lucasalvador/Reportes/CBAMECAPACITA/venv/lib/python3.12/site-packages/pandas/core/indexes/base.py", line 3812, in get_loc
    raise KeyError(key) from err
KeyError: 'id_certificacion'

2025-04-28 13:08:45,799 - INFO - Configuraci√≥n de Hugging Face cargada correctamente
2025-04-28 13:08:49,391 - ERROR - Error al cargar datos: Traceback (most recent call last):
  File "/home/lucasalvador/Reportes/CBAMECAPACITA/venv/lib/python3.12/site-packages/sqlalchemy/engine/base.py", line 1964, in _exec_single_context
    self.dialect.do_execute(
  File "/home/lucasalvador/Reportes/CBAMECAPACITA/venv/lib/python3.12/site-packages/sqlalchemy/engine/default.py", line 945, in do_execute
    cursor.execute(statement, parameters)
  File "/home/lucasalvador/Reportes/CBAMECAPACITA/venv/lib/python3.12/site-packages/pymysql/cursors.py", line 153, in execute
    result = self._query(query)
             ^^^^^^^^^^^^^^^^^^
  File "/home/lucasalvador/Reportes/CBAMECAPACITA/venv/lib/python3.12/site-packages/pymysql/cursors.py", line 322, in _query
    conn.query(q)
  File "/home/lucasalvador/Reportes/CBAMECAPACITA/venv/lib/python3.12/site-packages/pymysql/connections.py", line 563, in query
    self._affected_rows = self._read_query_result(unbuffered=unbuffered)
                          ^^^^^^^^^^^^^^^^^^^^^^^^^^^^^^^^^^^^^^^^^^^^^^
  File "/home/lucasalvador/Reportes/CBAMECAPACITA/venv/lib/python3.12/site-packages/pymysql/connections.py", line 825, in _read_query_result
    result.read()
  File "/home/lucasalvador/Reportes/CBAMECAPACITA/venv/lib/python3.12/site-packages/pymysql/connections.py", line 1199, in read
    first_packet = self.connection._read_packet()
                   ^^^^^^^^^^^^^^^^^^^^^^^^^^^^^^
  File "/home/lucasalvador/Reportes/CBAMECAPACITA/venv/lib/python3.12/site-packages/pymysql/connections.py", line 775, in _read_packet
    packet.raise_for_error()
  File "/home/lucasalvador/Reportes/CBAMECAPACITA/venv/lib/python3.12/site-packages/pymysql/protocol.py", line 219, in raise_for_error
    err.raise_mysql_exception(self._data)
  File "/home/lucasalvador/Reportes/CBAMECAPACITA/venv/lib/python3.12/site-packages/pymysql/err.py", line 150, in raise_mysql_exception
    raise errorclass(errno, errval)
pymysql.err.OperationalError: (1054, "Unknown column 'N_INSTITUCION' in 'SELECT'")

The above exception was the direct cause of the following exception:

Traceback (most recent call last):
  File "/home/lucasalvador/Reportes/CBAMECAPACITA/src/pages/comparar_cursos.py", line 44, in load_data
    df_historico = pd.read_sql(query_historico, engine)
                   ^^^^^^^^^^^^^^^^^^^^^^^^^^^^^^^^^^^^
  File "/home/lucasalvador/Reportes/CBAMECAPACITA/venv/lib/python3.12/site-packages/pandas/io/sql.py", line 734, in read_sql
    return pandas_sql.read_query(
           ^^^^^^^^^^^^^^^^^^^^^^
  File "/home/lucasalvador/Reportes/CBAMECAPACITA/venv/lib/python3.12/site-packages/pandas/io/sql.py", line 1836, in read_query
    result = self.execute(sql, params)
             ^^^^^^^^^^^^^^^^^^^^^^^^^
  File "/home/lucasalvador/Reportes/CBAMECAPACITA/venv/lib/python3.12/site-packages/pandas/io/sql.py", line 1659, in execute
    return self.con.exec_driver_sql(sql, *args)
           ^^^^^^^^^^^^^^^^^^^^^^^^^^^^^^^^^^^^
  File "/home/lucasalvador/Reportes/CBAMECAPACITA/venv/lib/python3.12/site-packages/sqlalchemy/engine/base.py", line 1776, in exec_driver_sql
    ret = self._execute_context(
          ^^^^^^^^^^^^^^^^^^^^^^
  File "/home/lucasalvador/Reportes/CBAMECAPACITA/venv/lib/python3.12/site-packages/sqlalchemy/engine/base.py", line 1843, in _execute_context
    return self._exec_single_context(
           ^^^^^^^^^^^^^^^^^^^^^^^^^^
  File "/home/lucasalvador/Reportes/CBAMECAPACITA/venv/lib/python3.12/site-packages/sqlalchemy/engine/base.py", line 1983, in _exec_single_context
    self._handle_dbapi_exception(
  File "/home/lucasalvador/Reportes/CBAMECAPACITA/venv/lib/python3.12/site-packages/sqlalchemy/engine/base.py", line 2352, in _handle_dbapi_exception
    raise sqlalchemy_exception.with_traceback(exc_info[2]) from e
  File "/home/lucasalvador/Reportes/CBAMECAPACITA/venv/lib/python3.12/site-packages/sqlalchemy/engine/base.py", line 1964, in _exec_single_context
    self.dialect.do_execute(
  File "/home/lucasalvador/Reportes/CBAMECAPACITA/venv/lib/python3.12/site-packages/sqlalchemy/engine/default.py", line 945, in do_execute
    cursor.execute(statement, parameters)
  File "/home/lucasalvador/Reportes/CBAMECAPACITA/venv/lib/python3.12/site-packages/pymysql/cursors.py", line 153, in execute
    result = self._query(query)
             ^^^^^^^^^^^^^^^^^^
  File "/home/lucasalvador/Reportes/CBAMECAPACITA/venv/lib/python3.12/site-packages/pymysql/cursors.py", line 322, in _query
    conn.query(q)
  File "/home/lucasalvador/Reportes/CBAMECAPACITA/venv/lib/python3.12/site-packages/pymysql/connections.py", line 563, in query
    self._affected_rows = self._read_query_result(unbuffered=unbuffered)
                          ^^^^^^^^^^^^^^^^^^^^^^^^^^^^^^^^^^^^^^^^^^^^^^
  File "/home/lucasalvador/Reportes/CBAMECAPACITA/venv/lib/python3.12/site-packages/pymysql/connections.py", line 825, in _read_query_result
    result.read()
  File "/home/lucasalvador/Reportes/CBAMECAPACITA/venv/lib/python3.12/site-packages/pymysql/connections.py", line 1199, in read
    first_packet = self.connection._read_packet()
                   ^^^^^^^^^^^^^^^^^^^^^^^^^^^^^^
  File "/home/lucasalvador/Reportes/CBAMECAPACITA/venv/lib/python3.12/site-packages/pymysql/connections.py", line 775, in _read_packet
    packet.raise_for_error()
  File "/home/lucasalvador/Reportes/CBAMECAPACITA/venv/lib/python3.12/site-packages/pymysql/protocol.py", line 219, in raise_for_error
    err.raise_mysql_exception(self._data)
  File "/home/lucasalvador/Reportes/CBAMECAPACITA/venv/lib/python3.12/site-packages/pymysql/err.py", line 150, in raise_mysql_exception
    raise errorclass(errno, errval)
sqlalchemy.exc.OperationalError: (pymysql.err.OperationalError) (1054, "Unknown column 'N_INSTITUCION' in 'SELECT'")
[SQL: 
            SELECT DISTINCT N_CURSO, N_SECTOR, N_INSTITUCION 
            FROM T_CURSOS_HISTORICO 
            ORDER BY N_CURSO
        ]
(Background on this error at: https://sqlalche.me/e/20/e3q8)

2025-04-28 13:09:07,858 - INFO - Configuraci√≥n de Hugging Face cargada correctamente
2025-04-28 13:09:18,593 - ERROR - Error en an√°lisis de compatibilidad: Traceback (most recent call last):
  File "/home/lucasalvador/Reportes/CBAMECAPACITA/venv/lib/python3.12/site-packages/pandas/core/indexes/base.py", line 3805, in get_loc
    return self._engine.get_loc(casted_key)
           ^^^^^^^^^^^^^^^^^^^^^^^^^^^^^^^^
  File "index.pyx", line 167, in pandas._libs.index.IndexEngine.get_loc
  File "index.pyx", line 196, in pandas._libs.index.IndexEngine.get_loc
  File "pandas/_libs/hashtable_class_helper.pxi", line 7081, in pandas._libs.hashtable.PyObjectHashTable.get_item
  File "pandas/_libs/hashtable_class_helper.pxi", line 7089, in pandas._libs.hashtable.PyObjectHashTable.get_item
KeyError: 'id_certificacion'

The above exception was the direct cause of the following exception:

Traceback (most recent call last):
  File "/home/lucasalvador/Reportes/CBAMECAPACITA/src/pages/comparar_cursos.py", line 113, in analizar_compatibilidad
    df_certificaciones['id_certificacion'].unique(),
    ~~~~~~~~~~~~~~~~~~^^^^^^^^^^^^^^^^^^^^
  File "/home/lucasalvador/Reportes/CBAMECAPACITA/venv/lib/python3.12/site-packages/pandas/core/frame.py", line 4102, in __getitem__
    indexer = self.columns.get_loc(key)
              ^^^^^^^^^^^^^^^^^^^^^^^^^
  File "/home/lucasalvador/Reportes/CBAMECAPACITA/venv/lib/python3.12/site-packages/pandas/core/indexes/base.py", line 3812, in get_loc
    raise KeyError(key) from err
KeyError: 'id_certificacion'

2025-04-28 13:09:34,195 - INFO - Configuraci√≥n de Hugging Face cargada correctamente
2025-04-28 13:09:44,791 - ERROR - Error en an√°lisis de compatibilidad: Traceback (most recent call last):
  File "/home/lucasalvador/Reportes/CBAMECAPACITA/venv/lib/python3.12/site-packages/pandas/core/indexes/base.py", line 3805, in get_loc
    return self._engine.get_loc(casted_key)
           ^^^^^^^^^^^^^^^^^^^^^^^^^^^^^^^^
  File "index.pyx", line 167, in pandas._libs.index.IndexEngine.get_loc
  File "index.pyx", line 196, in pandas._libs.index.IndexEngine.get_loc
  File "pandas/_libs/hashtable_class_helper.pxi", line 7081, in pandas._libs.hashtable.PyObjectHashTable.get_item
  File "pandas/_libs/hashtable_class_helper.pxi", line 7089, in pandas._libs.hashtable.PyObjectHashTable.get_item
KeyError: 'id_certificacion'

The above exception was the direct cause of the following exception:

Traceback (most recent call last):
  File "/home/lucasalvador/Reportes/CBAMECAPACITA/src/pages/comparar_cursos.py", line 113, in analizar_compatibilidad
    df_certificaciones['id_certificacion'].unique(),
    ~~~~~~~~~~~~~~~~~~^^^^^^^^^^^^^^^^^^^^
  File "/home/lucasalvador/Reportes/CBAMECAPACITA/venv/lib/python3.12/site-packages/pandas/core/frame.py", line 4102, in __getitem__
    indexer = self.columns.get_loc(key)
              ^^^^^^^^^^^^^^^^^^^^^^^^^
  File "/home/lucasalvador/Reportes/CBAMECAPACITA/venv/lib/python3.12/site-packages/pandas/core/indexes/base.py", line 3812, in get_loc
    raise KeyError(key) from err
KeyError: 'id_certificacion'

2025-04-28 13:14:04,750 - INFO - Configuraci√≥n de Hugging Face cargada correctamente
2025-04-28 13:14:15,909 - ERROR - Error en an√°lisis de compatibilidad: Traceback (most recent call last):
  File "/home/lucasalvador/Reportes/CBAMECAPACITA/venv/lib/python3.12/site-packages/pandas/core/indexes/base.py", line 3805, in get_loc
    return self._engine.get_loc(casted_key)
           ^^^^^^^^^^^^^^^^^^^^^^^^^^^^^^^^
  File "index.pyx", line 167, in pandas._libs.index.IndexEngine.get_loc
  File "index.pyx", line 196, in pandas._libs.index.IndexEngine.get_loc
  File "pandas/_libs/hashtable_class_helper.pxi", line 7081, in pandas._libs.hashtable.PyObjectHashTable.get_item
  File "pandas/_libs/hashtable_class_helper.pxi", line 7089, in pandas._libs.hashtable.PyObjectHashTable.get_item
KeyError: 'id_certificacion'

The above exception was the direct cause of the following exception:

Traceback (most recent call last):
  File "/home/lucasalvador/Reportes/CBAMECAPACITA/src/pages/comparar_cursos.py", line 113, in analizar_compatibilidad
    df_certificaciones['id_certificacion'].unique(),
    ~~~~~~~~~~~~~~~~~~^^^^^^^^^^^^^^^^^^^^
  File "/home/lucasalvador/Reportes/CBAMECAPACITA/venv/lib/python3.12/site-packages/pandas/core/frame.py", line 4102, in __getitem__
    indexer = self.columns.get_loc(key)
              ^^^^^^^^^^^^^^^^^^^^^^^^^
  File "/home/lucasalvador/Reportes/CBAMECAPACITA/venv/lib/python3.12/site-packages/pandas/core/indexes/base.py", line 3812, in get_loc
    raise KeyError(key) from err
KeyError: 'id_certificacion'

2025-04-28 13:14:34,383 - INFO - Configuraci√≥n de Hugging Face cargada correctamente
2025-04-28 13:14:45,388 - ERROR - Error en an√°lisis de compatibilidad: Traceback (most recent call last):
  File "/home/lucasalvador/Reportes/CBAMECAPACITA/venv/lib/python3.12/site-packages/pandas/core/indexes/base.py", line 3805, in get_loc
    return self._engine.get_loc(casted_key)
           ^^^^^^^^^^^^^^^^^^^^^^^^^^^^^^^^
  File "index.pyx", line 167, in pandas._libs.index.IndexEngine.get_loc
  File "index.pyx", line 196, in pandas._libs.index.IndexEngine.get_loc
  File "pandas/_libs/hashtable_class_helper.pxi", line 7081, in pandas._libs.hashtable.PyObjectHashTable.get_item
  File "pandas/_libs/hashtable_class_helper.pxi", line 7089, in pandas._libs.hashtable.PyObjectHashTable.get_item
KeyError: 'id_certificacion'

The above exception was the direct cause of the following exception:

Traceback (most recent call last):
  File "/home/lucasalvador/Reportes/CBAMECAPACITA/src/pages/comparar_cursos.py", line 134, in analizar_compatibilidad
    df_certificaciones['id_certificacion'].unique(),
    ~~~~~~~~~~~~~~~~~~^^^^^^^^^^^^^^^^^^^^
  File "/home/lucasalvador/Reportes/CBAMECAPACITA/venv/lib/python3.12/site-packages/pandas/core/frame.py", line 4102, in __getitem__
    indexer = self.columns.get_loc(key)
              ^^^^^^^^^^^^^^^^^^^^^^^^^
  File "/home/lucasalvador/Reportes/CBAMECAPACITA/venv/lib/python3.12/site-packages/pandas/core/indexes/base.py", line 3812, in get_loc
    raise KeyError(key) from err
KeyError: 'id_certificacion'

2025-04-28 13:15:16,119 - INFO - Configuraci√≥n de Hugging Face cargada correctamente
2025-04-28 13:15:29,739 - ERROR - Error al cargar equivalencias: Traceback (most recent call last):
  File "/home/lucasalvador/Reportes/CBAMECAPACITA/venv/lib/python3.12/site-packages/sqlalchemy/engine/base.py", line 1964, in _exec_single_context
    self.dialect.do_execute(
  File "/home/lucasalvador/Reportes/CBAMECAPACITA/venv/lib/python3.12/site-packages/sqlalchemy/engine/default.py", line 945, in do_execute
    cursor.execute(statement, parameters)
  File "/home/lucasalvador/Reportes/CBAMECAPACITA/venv/lib/python3.12/site-packages/pymysql/cursors.py", line 153, in execute
    result = self._query(query)
             ^^^^^^^^^^^^^^^^^^
  File "/home/lucasalvador/Reportes/CBAMECAPACITA/venv/lib/python3.12/site-packages/pymysql/cursors.py", line 322, in _query
    conn.query(q)
  File "/home/lucasalvador/Reportes/CBAMECAPACITA/venv/lib/python3.12/site-packages/pymysql/connections.py", line 563, in query
    self._affected_rows = self._read_query_result(unbuffered=unbuffered)
                          ^^^^^^^^^^^^^^^^^^^^^^^^^^^^^^^^^^^^^^^^^^^^^^
  File "/home/lucasalvador/Reportes/CBAMECAPACITA/venv/lib/python3.12/site-packages/pymysql/connections.py", line 825, in _read_query_result
    result.read()
  File "/home/lucasalvador/Reportes/CBAMECAPACITA/venv/lib/python3.12/site-packages/pymysql/connections.py", line 1199, in read
    first_packet = self.connection._read_packet()
                   ^^^^^^^^^^^^^^^^^^^^^^^^^^^^^^
  File "/home/lucasalvador/Reportes/CBAMECAPACITA/venv/lib/python3.12/site-packages/pymysql/connections.py", line 775, in _read_packet
    packet.raise_for_error()
  File "/home/lucasalvador/Reportes/CBAMECAPACITA/venv/lib/python3.12/site-packages/pymysql/protocol.py", line 219, in raise_for_error
    err.raise_mysql_exception(self._data)
  File "/home/lucasalvador/Reportes/CBAMECAPACITA/venv/lib/python3.12/site-packages/pymysql/err.py", line 150, in raise_mysql_exception
    raise errorclass(errno, errval)
pymysql.err.ProgrammingError: (1146, "Table 'CBAMECAPACITA.T_EQUIVALENCIAS_CURSOS' doesn't exist")

The above exception was the direct cause of the following exception:

Traceback (most recent call last):
  File "/home/lucasalvador/Reportes/CBAMECAPACITA/src/pages/comparar_cursos.py", line 179, in analizar_compatibilidad
    df_equivalencias = pd.read_sql(query, engine)
                       ^^^^^^^^^^^^^^^^^^^^^^^^^^
  File "/home/lucasalvador/Reportes/CBAMECAPACITA/venv/lib/python3.12/site-packages/pandas/io/sql.py", line 734, in read_sql
    return pandas_sql.read_query(
           ^^^^^^^^^^^^^^^^^^^^^^
  File "/home/lucasalvador/Reportes/CBAMECAPACITA/venv/lib/python3.12/site-packages/pandas/io/sql.py", line 1836, in read_query
    result = self.execute(sql, params)
             ^^^^^^^^^^^^^^^^^^^^^^^^^
  File "/home/lucasalvador/Reportes/CBAMECAPACITA/venv/lib/python3.12/site-packages/pandas/io/sql.py", line 1659, in execute
    return self.con.exec_driver_sql(sql, *args)
           ^^^^^^^^^^^^^^^^^^^^^^^^^^^^^^^^^^^^
  File "/home/lucasalvador/Reportes/CBAMECAPACITA/venv/lib/python3.12/site-packages/sqlalchemy/engine/base.py", line 1776, in exec_driver_sql
    ret = self._execute_context(
          ^^^^^^^^^^^^^^^^^^^^^^
  File "/home/lucasalvador/Reportes/CBAMECAPACITA/venv/lib/python3.12/site-packages/sqlalchemy/engine/base.py", line 1843, in _execute_context
    return self._exec_single_context(
           ^^^^^^^^^^^^^^^^^^^^^^^^^^
  File "/home/lucasalvador/Reportes/CBAMECAPACITA/venv/lib/python3.12/site-packages/sqlalchemy/engine/base.py", line 1983, in _exec_single_context
    self._handle_dbapi_exception(
  File "/home/lucasalvador/Reportes/CBAMECAPACITA/venv/lib/python3.12/site-packages/sqlalchemy/engine/base.py", line 2352, in _handle_dbapi_exception
    raise sqlalchemy_exception.with_traceback(exc_info[2]) from e
  File "/home/lucasalvador/Reportes/CBAMECAPACITA/venv/lib/python3.12/site-packages/sqlalchemy/engine/base.py", line 1964, in _exec_single_context
    self.dialect.do_execute(
  File "/home/lucasalvador/Reportes/CBAMECAPACITA/venv/lib/python3.12/site-packages/sqlalchemy/engine/default.py", line 945, in do_execute
    cursor.execute(statement, parameters)
  File "/home/lucasalvador/Reportes/CBAMECAPACITA/venv/lib/python3.12/site-packages/pymysql/cursors.py", line 153, in execute
    result = self._query(query)
             ^^^^^^^^^^^^^^^^^^
  File "/home/lucasalvador/Reportes/CBAMECAPACITA/venv/lib/python3.12/site-packages/pymysql/cursors.py", line 322, in _query
    conn.query(q)
  File "/home/lucasalvador/Reportes/CBAMECAPACITA/venv/lib/python3.12/site-packages/pymysql/connections.py", line 563, in query
    self._affected_rows = self._read_query_result(unbuffered=unbuffered)
                          ^^^^^^^^^^^^^^^^^^^^^^^^^^^^^^^^^^^^^^^^^^^^^^
  File "/home/lucasalvador/Reportes/CBAMECAPACITA/venv/lib/python3.12/site-packages/pymysql/connections.py", line 825, in _read_query_result
    result.read()
  File "/home/lucasalvador/Reportes/CBAMECAPACITA/venv/lib/python3.12/site-packages/pymysql/connections.py", line 1199, in read
    first_packet = self.connection._read_packet()
                   ^^^^^^^^^^^^^^^^^^^^^^^^^^^^^^
  File "/home/lucasalvador/Reportes/CBAMECAPACITA/venv/lib/python3.12/site-packages/pymysql/connections.py", line 775, in _read_packet
    packet.raise_for_error()
  File "/home/lucasalvador/Reportes/CBAMECAPACITA/venv/lib/python3.12/site-packages/pymysql/protocol.py", line 219, in raise_for_error
    err.raise_mysql_exception(self._data)
  File "/home/lucasalvador/Reportes/CBAMECAPACITA/venv/lib/python3.12/site-packages/pymysql/err.py", line 150, in raise_mysql_exception
    raise errorclass(errno, errval)
sqlalchemy.exc.ProgrammingError: (pymysql.err.ProgrammingError) (1146, "Table 'CBAMECAPACITA.T_EQUIVALENCIAS_CURSOS' doesn't exist")
[SQL: 
                        SELECT * FROM T_EQUIVALENCIAS_CURSOS
                        ORDER BY fecha_creacion DESC
                    ]
(Background on this error at: https://sqlalche.me/e/20/f405)

2025-04-28 13:18:17,814 - INFO - Configuraci√≥n de Hugging Face cargada correctamente
2025-04-28 13:18:31,451 - ERROR - Error al cargar equivalencias: Traceback (most recent call last):
  File "/home/lucasalvador/Reportes/CBAMECAPACITA/venv/lib/python3.12/site-packages/sqlalchemy/engine/base.py", line 1964, in _exec_single_context
    self.dialect.do_execute(
  File "/home/lucasalvador/Reportes/CBAMECAPACITA/venv/lib/python3.12/site-packages/sqlalchemy/engine/default.py", line 945, in do_execute
    cursor.execute(statement, parameters)
  File "/home/lucasalvador/Reportes/CBAMECAPACITA/venv/lib/python3.12/site-packages/pymysql/cursors.py", line 153, in execute
    result = self._query(query)
             ^^^^^^^^^^^^^^^^^^
  File "/home/lucasalvador/Reportes/CBAMECAPACITA/venv/lib/python3.12/site-packages/pymysql/cursors.py", line 322, in _query
    conn.query(q)
  File "/home/lucasalvador/Reportes/CBAMECAPACITA/venv/lib/python3.12/site-packages/pymysql/connections.py", line 563, in query
    self._affected_rows = self._read_query_result(unbuffered=unbuffered)
                          ^^^^^^^^^^^^^^^^^^^^^^^^^^^^^^^^^^^^^^^^^^^^^^
  File "/home/lucasalvador/Reportes/CBAMECAPACITA/venv/lib/python3.12/site-packages/pymysql/connections.py", line 825, in _read_query_result
    result.read()
  File "/home/lucasalvador/Reportes/CBAMECAPACITA/venv/lib/python3.12/site-packages/pymysql/connections.py", line 1199, in read
    first_packet = self.connection._read_packet()
                   ^^^^^^^^^^^^^^^^^^^^^^^^^^^^^^
  File "/home/lucasalvador/Reportes/CBAMECAPACITA/venv/lib/python3.12/site-packages/pymysql/connections.py", line 775, in _read_packet
    packet.raise_for_error()
  File "/home/lucasalvador/Reportes/CBAMECAPACITA/venv/lib/python3.12/site-packages/pymysql/protocol.py", line 219, in raise_for_error
    err.raise_mysql_exception(self._data)
  File "/home/lucasalvador/Reportes/CBAMECAPACITA/venv/lib/python3.12/site-packages/pymysql/err.py", line 150, in raise_mysql_exception
    raise errorclass(errno, errval)
pymysql.err.OperationalError: (1054, "Unknown column 'c.nombre_certificacion' in 'SELECT'")

The above exception was the direct cause of the following exception:

Traceback (most recent call last):
  File "/home/lucasalvador/Reportes/CBAMECAPACITA/src/pages/comparar_cursos.py", line 177, in analizar_compatibilidad
    df_equivalencias = pd.read_sql(query, engine)
                       ^^^^^^^^^^^^^^^^^^^^^^^^^^
  File "/home/lucasalvador/Reportes/CBAMECAPACITA/venv/lib/python3.12/site-packages/pandas/io/sql.py", line 734, in read_sql
    return pandas_sql.read_query(
           ^^^^^^^^^^^^^^^^^^^^^^
  File "/home/lucasalvador/Reportes/CBAMECAPACITA/venv/lib/python3.12/site-packages/pandas/io/sql.py", line 1836, in read_query
    result = self.execute(sql, params)
             ^^^^^^^^^^^^^^^^^^^^^^^^^
  File "/home/lucasalvador/Reportes/CBAMECAPACITA/venv/lib/python3.12/site-packages/pandas/io/sql.py", line 1659, in execute
    return self.con.exec_driver_sql(sql, *args)
           ^^^^^^^^^^^^^^^^^^^^^^^^^^^^^^^^^^^^
  File "/home/lucasalvador/Reportes/CBAMECAPACITA/venv/lib/python3.12/site-packages/sqlalchemy/engine/base.py", line 1776, in exec_driver_sql
    ret = self._execute_context(
          ^^^^^^^^^^^^^^^^^^^^^^
  File "/home/lucasalvador/Reportes/CBAMECAPACITA/venv/lib/python3.12/site-packages/sqlalchemy/engine/base.py", line 1843, in _execute_context
    return self._exec_single_context(
           ^^^^^^^^^^^^^^^^^^^^^^^^^^
  File "/home/lucasalvador/Reportes/CBAMECAPACITA/venv/lib/python3.12/site-packages/sqlalchemy/engine/base.py", line 1983, in _exec_single_context
    self._handle_dbapi_exception(
  File "/home/lucasalvador/Reportes/CBAMECAPACITA/venv/lib/python3.12/site-packages/sqlalchemy/engine/base.py", line 2352, in _handle_dbapi_exception
    raise sqlalchemy_exception.with_traceback(exc_info[2]) from e
  File "/home/lucasalvador/Reportes/CBAMECAPACITA/venv/lib/python3.12/site-packages/sqlalchemy/engine/base.py", line 1964, in _exec_single_context
    self.dialect.do_execute(
  File "/home/lucasalvador/Reportes/CBAMECAPACITA/venv/lib/python3.12/site-packages/sqlalchemy/engine/default.py", line 945, in do_execute
    cursor.execute(statement, parameters)
  File "/home/lucasalvador/Reportes/CBAMECAPACITA/venv/lib/python3.12/site-packages/pymysql/cursors.py", line 153, in execute
    result = self._query(query)
             ^^^^^^^^^^^^^^^^^^
  File "/home/lucasalvador/Reportes/CBAMECAPACITA/venv/lib/python3.12/site-packages/pymysql/cursors.py", line 322, in _query
    conn.query(q)
  File "/home/lucasalvador/Reportes/CBAMECAPACITA/venv/lib/python3.12/site-packages/pymysql/connections.py", line 563, in query
    self._affected_rows = self._read_query_result(unbuffered=unbuffered)
                          ^^^^^^^^^^^^^^^^^^^^^^^^^^^^^^^^^^^^^^^^^^^^^^
  File "/home/lucasalvador/Reportes/CBAMECAPACITA/venv/lib/python3.12/site-packages/pymysql/connections.py", line 825, in _read_query_result
    result.read()
  File "/home/lucasalvador/Reportes/CBAMECAPACITA/venv/lib/python3.12/site-packages/pymysql/connections.py", line 1199, in read
    first_packet = self.connection._read_packet()
                   ^^^^^^^^^^^^^^^^^^^^^^^^^^^^^^
  File "/home/lucasalvador/Reportes/CBAMECAPACITA/venv/lib/python3.12/site-packages/pymysql/connections.py", line 775, in _read_packet
    packet.raise_for_error()
  File "/home/lucasalvador/Reportes/CBAMECAPACITA/venv/lib/python3.12/site-packages/pymysql/protocol.py", line 219, in raise_for_error
    err.raise_mysql_exception(self._data)
  File "/home/lucasalvador/Reportes/CBAMECAPACITA/venv/lib/python3.12/site-packages/pymysql/err.py", line 150, in raise_mysql_exception
    raise errorclass(errno, errval)
sqlalchemy.exc.OperationalError: (pymysql.err.OperationalError) (1054, "Unknown column 'c.nombre_certificacion' in 'SELECT'")
[SQL: 
                        SELECT 
                            ec.id_equivalencia,
                            ec.n_curso,
                            ec.n_certificacion,
                            c.nombre_certificacion,
                            ec.fecha_creacion
                        FROM T_EQUIVALENCIAS_CURSOS ec
                        LEFT JOIN T_CERTIF_X_LOCALIDAD c ON ec.n_certificacion = c.N_CERTIFICACION
                        ORDER BY ec.fecha_creacion DESC
                    ]
(Background on this error at: https://sqlalche.me/e/20/e3q8)

2025-04-28 13:18:39,043 - INFO - Configuraci√≥n de Hugging Face cargada correctamente
2025-04-28 13:18:52,623 - ERROR - Error al guardar equivalencia: Traceback (most recent call last):
  File "/home/lucasalvador/Reportes/CBAMECAPACITA/src/pages/comparar_cursos.py", line 151, in analizar_compatibilidad
    conn.execute("""
  File "/home/lucasalvador/Reportes/CBAMECAPACITA/venv/lib/python3.12/site-packages/sqlalchemy/engine/base.py", line 1410, in execute
    distilled_parameters = _distill_params_20(parameters)
                           ^^^^^^^^^^^^^^^^^^^^^^^^^^^^^^
  File "lib/sqlalchemy/cyextension/util.pyx", line 32, in sqlalchemy.cyextension.util._distill_params_20
  File "lib/sqlalchemy/cyextension/util.pyx", line 23, in sqlalchemy.cyextension.util._check_item
sqlalchemy.exc.ArgumentError: List argument must consist only of tuples or dictionaries

2025-04-28 13:18:55,337 - ERROR - Error al cargar equivalencias: Traceback (most recent call last):
  File "/home/lucasalvador/Reportes/CBAMECAPACITA/venv/lib/python3.12/site-packages/sqlalchemy/engine/base.py", line 1964, in _exec_single_context
    self.dialect.do_execute(
  File "/home/lucasalvador/Reportes/CBAMECAPACITA/venv/lib/python3.12/site-packages/sqlalchemy/engine/default.py", line 945, in do_execute
    cursor.execute(statement, parameters)
  File "/home/lucasalvador/Reportes/CBAMECAPACITA/venv/lib/python3.12/site-packages/pymysql/cursors.py", line 153, in execute
    result = self._query(query)
             ^^^^^^^^^^^^^^^^^^
  File "/home/lucasalvador/Reportes/CBAMECAPACITA/venv/lib/python3.12/site-packages/pymysql/cursors.py", line 322, in _query
    conn.query(q)
  File "/home/lucasalvador/Reportes/CBAMECAPACITA/venv/lib/python3.12/site-packages/pymysql/connections.py", line 563, in query
    self._affected_rows = self._read_query_result(unbuffered=unbuffered)
                          ^^^^^^^^^^^^^^^^^^^^^^^^^^^^^^^^^^^^^^^^^^^^^^
  File "/home/lucasalvador/Reportes/CBAMECAPACITA/venv/lib/python3.12/site-packages/pymysql/connections.py", line 825, in _read_query_result
    result.read()
  File "/home/lucasalvador/Reportes/CBAMECAPACITA/venv/lib/python3.12/site-packages/pymysql/connections.py", line 1199, in read
    first_packet = self.connection._read_packet()
                   ^^^^^^^^^^^^^^^^^^^^^^^^^^^^^^
  File "/home/lucasalvador/Reportes/CBAMECAPACITA/venv/lib/python3.12/site-packages/pymysql/connections.py", line 775, in _read_packet
    packet.raise_for_error()
  File "/home/lucasalvador/Reportes/CBAMECAPACITA/venv/lib/python3.12/site-packages/pymysql/protocol.py", line 219, in raise_for_error
    err.raise_mysql_exception(self._data)
  File "/home/lucasalvador/Reportes/CBAMECAPACITA/venv/lib/python3.12/site-packages/pymysql/err.py", line 150, in raise_mysql_exception
    raise errorclass(errno, errval)
pymysql.err.OperationalError: (1054, "Unknown column 'c.nombre_certificacion' in 'SELECT'")

The above exception was the direct cause of the following exception:

Traceback (most recent call last):
  File "/home/lucasalvador/Reportes/CBAMECAPACITA/src/pages/comparar_cursos.py", line 177, in analizar_compatibilidad
    df_equivalencias = pd.read_sql(query, engine)
                       ^^^^^^^^^^^^^^^^^^^^^^^^^^
  File "/home/lucasalvador/Reportes/CBAMECAPACITA/venv/lib/python3.12/site-packages/pandas/io/sql.py", line 734, in read_sql
    return pandas_sql.read_query(
           ^^^^^^^^^^^^^^^^^^^^^^
  File "/home/lucasalvador/Reportes/CBAMECAPACITA/venv/lib/python3.12/site-packages/pandas/io/sql.py", line 1836, in read_query
    result = self.execute(sql, params)
             ^^^^^^^^^^^^^^^^^^^^^^^^^
  File "/home/lucasalvador/Reportes/CBAMECAPACITA/venv/lib/python3.12/site-packages/pandas/io/sql.py", line 1659, in execute
    return self.con.exec_driver_sql(sql, *args)
           ^^^^^^^^^^^^^^^^^^^^^^^^^^^^^^^^^^^^
  File "/home/lucasalvador/Reportes/CBAMECAPACITA/venv/lib/python3.12/site-packages/sqlalchemy/engine/base.py", line 1776, in exec_driver_sql
    ret = self._execute_context(
          ^^^^^^^^^^^^^^^^^^^^^^
  File "/home/lucasalvador/Reportes/CBAMECAPACITA/venv/lib/python3.12/site-packages/sqlalchemy/engine/base.py", line 1843, in _execute_context
    return self._exec_single_context(
           ^^^^^^^^^^^^^^^^^^^^^^^^^^
  File "/home/lucasalvador/Reportes/CBAMECAPACITA/venv/lib/python3.12/site-packages/sqlalchemy/engine/base.py", line 1983, in _exec_single_context
    self._handle_dbapi_exception(
  File "/home/lucasalvador/Reportes/CBAMECAPACITA/venv/lib/python3.12/site-packages/sqlalchemy/engine/base.py", line 2352, in _handle_dbapi_exception
    raise sqlalchemy_exception.with_traceback(exc_info[2]) from e
  File "/home/lucasalvador/Reportes/CBAMECAPACITA/venv/lib/python3.12/site-packages/sqlalchemy/engine/base.py", line 1964, in _exec_single_context
    self.dialect.do_execute(
  File "/home/lucasalvador/Reportes/CBAMECAPACITA/venv/lib/python3.12/site-packages/sqlalchemy/engine/default.py", line 945, in do_execute
    cursor.execute(statement, parameters)
  File "/home/lucasalvador/Reportes/CBAMECAPACITA/venv/lib/python3.12/site-packages/pymysql/cursors.py", line 153, in execute
    result = self._query(query)
             ^^^^^^^^^^^^^^^^^^
  File "/home/lucasalvador/Reportes/CBAMECAPACITA/venv/lib/python3.12/site-packages/pymysql/cursors.py", line 322, in _query
    conn.query(q)
  File "/home/lucasalvador/Reportes/CBAMECAPACITA/venv/lib/python3.12/site-packages/pymysql/connections.py", line 563, in query
    self._affected_rows = self._read_query_result(unbuffered=unbuffered)
                          ^^^^^^^^^^^^^^^^^^^^^^^^^^^^^^^^^^^^^^^^^^^^^^
  File "/home/lucasalvador/Reportes/CBAMECAPACITA/venv/lib/python3.12/site-packages/pymysql/connections.py", line 825, in _read_query_result
    result.read()
  File "/home/lucasalvador/Reportes/CBAMECAPACITA/venv/lib/python3.12/site-packages/pymysql/connections.py", line 1199, in read
    first_packet = self.connection._read_packet()
                   ^^^^^^^^^^^^^^^^^^^^^^^^^^^^^^
  File "/home/lucasalvador/Reportes/CBAMECAPACITA/venv/lib/python3.12/site-packages/pymysql/connections.py", line 775, in _read_packet
    packet.raise_for_error()
  File "/home/lucasalvador/Reportes/CBAMECAPACITA/venv/lib/python3.12/site-packages/pymysql/protocol.py", line 219, in raise_for_error
    err.raise_mysql_exception(self._data)
  File "/home/lucasalvador/Reportes/CBAMECAPACITA/venv/lib/python3.12/site-packages/pymysql/err.py", line 150, in raise_mysql_exception
    raise errorclass(errno, errval)
sqlalchemy.exc.OperationalError: (pymysql.err.OperationalError) (1054, "Unknown column 'c.nombre_certificacion' in 'SELECT'")
[SQL: 
                        SELECT 
                            ec.id_equivalencia,
                            ec.n_curso,
                            ec.n_certificacion,
                            c.nombre_certificacion,
                            ec.fecha_creacion
                        FROM T_EQUIVALENCIAS_CURSOS ec
                        LEFT JOIN T_CERTIF_X_LOCALIDAD c ON ec.n_certificacion = c.N_CERTIFICACION
                        ORDER BY ec.fecha_creacion DESC
                    ]
(Background on this error at: https://sqlalche.me/e/20/e3q8)

2025-04-28 13:19:32,166 - INFO - Configuraci√≥n de Hugging Face cargada correctamente
2025-04-28 13:19:45,884 - ERROR - Error al cargar equivalencias: Traceback (most recent call last):
  File "/home/lucasalvador/Reportes/CBAMECAPACITA/venv/lib/python3.12/site-packages/sqlalchemy/engine/base.py", line 1964, in _exec_single_context
    self.dialect.do_execute(
  File "/home/lucasalvador/Reportes/CBAMECAPACITA/venv/lib/python3.12/site-packages/sqlalchemy/engine/default.py", line 945, in do_execute
    cursor.execute(statement, parameters)
  File "/home/lucasalvador/Reportes/CBAMECAPACITA/venv/lib/python3.12/site-packages/pymysql/cursors.py", line 153, in execute
    result = self._query(query)
             ^^^^^^^^^^^^^^^^^^
  File "/home/lucasalvador/Reportes/CBAMECAPACITA/venv/lib/python3.12/site-packages/pymysql/cursors.py", line 322, in _query
    conn.query(q)
  File "/home/lucasalvador/Reportes/CBAMECAPACITA/venv/lib/python3.12/site-packages/pymysql/connections.py", line 563, in query
    self._affected_rows = self._read_query_result(unbuffered=unbuffered)
                          ^^^^^^^^^^^^^^^^^^^^^^^^^^^^^^^^^^^^^^^^^^^^^^
  File "/home/lucasalvador/Reportes/CBAMECAPACITA/venv/lib/python3.12/site-packages/pymysql/connections.py", line 825, in _read_query_result
    result.read()
  File "/home/lucasalvador/Reportes/CBAMECAPACITA/venv/lib/python3.12/site-packages/pymysql/connections.py", line 1199, in read
    first_packet = self.connection._read_packet()
                   ^^^^^^^^^^^^^^^^^^^^^^^^^^^^^^
  File "/home/lucasalvador/Reportes/CBAMECAPACITA/venv/lib/python3.12/site-packages/pymysql/connections.py", line 775, in _read_packet
    packet.raise_for_error()
  File "/home/lucasalvador/Reportes/CBAMECAPACITA/venv/lib/python3.12/site-packages/pymysql/protocol.py", line 219, in raise_for_error
    err.raise_mysql_exception(self._data)
  File "/home/lucasalvador/Reportes/CBAMECAPACITA/venv/lib/python3.12/site-packages/pymysql/err.py", line 150, in raise_mysql_exception
    raise errorclass(errno, errval)
pymysql.err.OperationalError: (1054, "Unknown column 'ec.fecha_creacion' in 'SELECT'")

The above exception was the direct cause of the following exception:

Traceback (most recent call last):
  File "/home/lucasalvador/Reportes/CBAMECAPACITA/src/pages/comparar_cursos.py", line 175, in analizar_compatibilidad
    df_equivalencias = pd.read_sql(query, engine)
                       ^^^^^^^^^^^^^^^^^^^^^^^^^^
  File "/home/lucasalvador/Reportes/CBAMECAPACITA/venv/lib/python3.12/site-packages/pandas/io/sql.py", line 734, in read_sql
    return pandas_sql.read_query(
           ^^^^^^^^^^^^^^^^^^^^^^
  File "/home/lucasalvador/Reportes/CBAMECAPACITA/venv/lib/python3.12/site-packages/pandas/io/sql.py", line 1836, in read_query
    result = self.execute(sql, params)
             ^^^^^^^^^^^^^^^^^^^^^^^^^
  File "/home/lucasalvador/Reportes/CBAMECAPACITA/venv/lib/python3.12/site-packages/pandas/io/sql.py", line 1659, in execute
    return self.con.exec_driver_sql(sql, *args)
           ^^^^^^^^^^^^^^^^^^^^^^^^^^^^^^^^^^^^
  File "/home/lucasalvador/Reportes/CBAMECAPACITA/venv/lib/python3.12/site-packages/sqlalchemy/engine/base.py", line 1776, in exec_driver_sql
    ret = self._execute_context(
          ^^^^^^^^^^^^^^^^^^^^^^
  File "/home/lucasalvador/Reportes/CBAMECAPACITA/venv/lib/python3.12/site-packages/sqlalchemy/engine/base.py", line 1843, in _execute_context
    return self._exec_single_context(
           ^^^^^^^^^^^^^^^^^^^^^^^^^^
  File "/home/lucasalvador/Reportes/CBAMECAPACITA/venv/lib/python3.12/site-packages/sqlalchemy/engine/base.py", line 1983, in _exec_single_context
    self._handle_dbapi_exception(
  File "/home/lucasalvador/Reportes/CBAMECAPACITA/venv/lib/python3.12/site-packages/sqlalchemy/engine/base.py", line 2352, in _handle_dbapi_exception
    raise sqlalchemy_exception.with_traceback(exc_info[2]) from e
  File "/home/lucasalvador/Reportes/CBAMECAPACITA/venv/lib/python3.12/site-packages/sqlalchemy/engine/base.py", line 1964, in _exec_single_context
    self.dialect.do_execute(
  File "/home/lucasalvador/Reportes/CBAMECAPACITA/venv/lib/python3.12/site-packages/sqlalchemy/engine/default.py", line 945, in do_execute
    cursor.execute(statement, parameters)
  File "/home/lucasalvador/Reportes/CBAMECAPACITA/venv/lib/python3.12/site-packages/pymysql/cursors.py", line 153, in execute
    result = self._query(query)
             ^^^^^^^^^^^^^^^^^^
  File "/home/lucasalvador/Reportes/CBAMECAPACITA/venv/lib/python3.12/site-packages/pymysql/cursors.py", line 322, in _query
    conn.query(q)
  File "/home/lucasalvador/Reportes/CBAMECAPACITA/venv/lib/python3.12/site-packages/pymysql/connections.py", line 563, in query
    self._affected_rows = self._read_query_result(unbuffered=unbuffered)
                          ^^^^^^^^^^^^^^^^^^^^^^^^^^^^^^^^^^^^^^^^^^^^^^
  File "/home/lucasalvador/Reportes/CBAMECAPACITA/venv/lib/python3.12/site-packages/pymysql/connections.py", line 825, in _read_query_result
    result.read()
  File "/home/lucasalvador/Reportes/CBAMECAPACITA/venv/lib/python3.12/site-packages/pymysql/connections.py", line 1199, in read
    first_packet = self.connection._read_packet()
                   ^^^^^^^^^^^^^^^^^^^^^^^^^^^^^^
  File "/home/lucasalvador/Reportes/CBAMECAPACITA/venv/lib/python3.12/site-packages/pymysql/connections.py", line 775, in _read_packet
    packet.raise_for_error()
  File "/home/lucasalvador/Reportes/CBAMECAPACITA/venv/lib/python3.12/site-packages/pymysql/protocol.py", line 219, in raise_for_error
    err.raise_mysql_exception(self._data)
  File "/home/lucasalvador/Reportes/CBAMECAPACITA/venv/lib/python3.12/site-packages/pymysql/err.py", line 150, in raise_mysql_exception
    raise errorclass(errno, errval)
sqlalchemy.exc.OperationalError: (pymysql.err.OperationalError) (1054, "Unknown column 'ec.fecha_creacion' in 'SELECT'")
[SQL: 
                        SELECT 
                            ec.id_equivalencia,
                            ec.n_curso,
                            ec.n_certificacion,
                            ec.fecha_creacion
                        FROM T_EQUIVALENCIAS_CURSOS ec
                        ORDER BY ec.fecha_creacion DESC
                    ]
(Background on this error at: https://sqlalche.me/e/20/e3q8)

2025-04-28 13:21:14,440 - INFO - Configuraci√≥n de Hugging Face cargada correctamente
2025-04-28 13:21:31,783 - INFO - Configuraci√≥n de Hugging Face cargada correctamente
2025-04-28 13:21:44,172 - ERROR - Error al guardar equivalencia: Traceback (most recent call last):
  File "/home/lucasalvador/Reportes/CBAMECAPACITA/src/pages/comparar_cursos.py", line 151, in analizar_compatibilidad
    conn.execute("""
  File "/home/lucasalvador/Reportes/CBAMECAPACITA/venv/lib/python3.12/site-packages/sqlalchemy/engine/base.py", line 1410, in execute
    distilled_parameters = _distill_params_20(parameters)
                           ^^^^^^^^^^^^^^^^^^^^^^^^^^^^^^
  File "lib/sqlalchemy/cyextension/util.pyx", line 32, in sqlalchemy.cyextension.util._distill_params_20
  File "lib/sqlalchemy/cyextension/util.pyx", line 23, in sqlalchemy.cyextension.util._check_item
sqlalchemy.exc.ArgumentError: List argument must consist only of tuples or dictionaries

2025-04-28 13:24:09,787 - INFO - Configuraci√≥n de Hugging Face cargada correctamente
2025-04-28 13:24:26,164 - INFO - Configuraci√≥n de Hugging Face cargada correctamente
2025-04-28 13:24:38,973 - ERROR - Error al guardar equivalencia: Traceback (most recent call last):
  File "/home/lucasalvador/Reportes/CBAMECAPACITA/venv/lib/python3.12/site-packages/sqlalchemy/engine/base.py", line 1412, in execute
    meth = statement._execute_on_connection
           ^^^^^^^^^^^^^^^^^^^^^^^^^^^^^^^^
AttributeError: 'str' object has no attribute '_execute_on_connection'

The above exception was the direct cause of the following exception:

Traceback (most recent call last):
  File "/home/lucasalvador/Reportes/CBAMECAPACITA/src/pages/comparar_cursos.py", line 152, in analizar_compatibilidad
    conn.execute("""
  File "/home/lucasalvador/Reportes/CBAMECAPACITA/venv/lib/python3.12/site-packages/sqlalchemy/engine/base.py", line 1414, in execute
    raise exc.ObjectNotExecutableError(statement) from err
sqlalchemy.exc.ObjectNotExecutableError: Not an executable object: '\n                                INSERT INTO T_EQUIVALENCIAS_CURSOS (n_curso, n_certificacion)\n                                VALUES (%s, %s)\n                            '

2025-04-28 13:26:05,523 - INFO - Configuraci√≥n de Hugging Face cargada correctamente
2025-04-28 13:26:25,565 - INFO - Configuraci√≥n de Hugging Face cargada correctamente
2025-04-28 13:26:43,037 - INFO - Configuraci√≥n de Hugging Face cargada correctamente
2025-04-28 13:26:55,916 - ERROR - Error al guardar equivalencia: Traceback (most recent call last):
  File "/home/lucasalvador/Reportes/CBAMECAPACITA/venv/lib/python3.12/site-packages/sqlalchemy/engine/base.py", line 1964, in _exec_single_context
    self.dialect.do_execute(
  File "/home/lucasalvador/Reportes/CBAMECAPACITA/venv/lib/python3.12/site-packages/sqlalchemy/engine/default.py", line 945, in do_execute
    cursor.execute(statement, parameters)
  File "/home/lucasalvador/Reportes/CBAMECAPACITA/venv/lib/python3.12/site-packages/pymysql/cursors.py", line 153, in execute
    result = self._query(query)
             ^^^^^^^^^^^^^^^^^^
  File "/home/lucasalvador/Reportes/CBAMECAPACITA/venv/lib/python3.12/site-packages/pymysql/cursors.py", line 322, in _query
    conn.query(q)
  File "/home/lucasalvador/Reportes/CBAMECAPACITA/venv/lib/python3.12/site-packages/pymysql/connections.py", line 563, in query
    self._affected_rows = self._read_query_result(unbuffered=unbuffered)
                          ^^^^^^^^^^^^^^^^^^^^^^^^^^^^^^^^^^^^^^^^^^^^^^
  File "/home/lucasalvador/Reportes/CBAMECAPACITA/venv/lib/python3.12/site-packages/pymysql/connections.py", line 825, in _read_query_result
    result.read()
  File "/home/lucasalvador/Reportes/CBAMECAPACITA/venv/lib/python3.12/site-packages/pymysql/connections.py", line 1199, in read
    first_packet = self.connection._read_packet()
                   ^^^^^^^^^^^^^^^^^^^^^^^^^^^^^^
  File "/home/lucasalvador/Reportes/CBAMECAPACITA/venv/lib/python3.12/site-packages/pymysql/connections.py", line 775, in _read_packet
    packet.raise_for_error()
  File "/home/lucasalvador/Reportes/CBAMECAPACITA/venv/lib/python3.12/site-packages/pymysql/protocol.py", line 219, in raise_for_error
    err.raise_mysql_exception(self._data)
  File "/home/lucasalvador/Reportes/CBAMECAPACITA/venv/lib/python3.12/site-packages/pymysql/err.py", line 150, in raise_mysql_exception
    raise errorclass(errno, errval)
pymysql.err.DataError: (1406, "Data too long for column 'n_certificacion' at row 1")

The above exception was the direct cause of the following exception:

Traceback (most recent call last):
  File "/home/lucasalvador/Reportes/CBAMECAPACITA/src/pages/comparar_cursos.py", line 156, in analizar_compatibilidad
    conn.execute(sql, {"curso": curso_historico, "cert": certificacion})
  File "/home/lucasalvador/Reportes/CBAMECAPACITA/venv/lib/python3.12/site-packages/sqlalchemy/engine/base.py", line 1416, in execute
    return meth(
           ^^^^^
  File "/home/lucasalvador/Reportes/CBAMECAPACITA/venv/lib/python3.12/site-packages/sqlalchemy/sql/elements.py", line 523, in _execute_on_connection
    return connection._execute_clauseelement(
           ^^^^^^^^^^^^^^^^^^^^^^^^^^^^^^^^^^
  File "/home/lucasalvador/Reportes/CBAMECAPACITA/venv/lib/python3.12/site-packages/sqlalchemy/engine/base.py", line 1638, in _execute_clauseelement
    ret = self._execute_context(
          ^^^^^^^^^^^^^^^^^^^^^^
  File "/home/lucasalvador/Reportes/CBAMECAPACITA/venv/lib/python3.12/site-packages/sqlalchemy/engine/base.py", line 1843, in _execute_context
    return self._exec_single_context(
           ^^^^^^^^^^^^^^^^^^^^^^^^^^
  File "/home/lucasalvador/Reportes/CBAMECAPACITA/venv/lib/python3.12/site-packages/sqlalchemy/engine/base.py", line 1983, in _exec_single_context
    self._handle_dbapi_exception(
  File "/home/lucasalvador/Reportes/CBAMECAPACITA/venv/lib/python3.12/site-packages/sqlalchemy/engine/base.py", line 2352, in _handle_dbapi_exception
    raise sqlalchemy_exception.with_traceback(exc_info[2]) from e
  File "/home/lucasalvador/Reportes/CBAMECAPACITA/venv/lib/python3.12/site-packages/sqlalchemy/engine/base.py", line 1964, in _exec_single_context
    self.dialect.do_execute(
  File "/home/lucasalvador/Reportes/CBAMECAPACITA/venv/lib/python3.12/site-packages/sqlalchemy/engine/default.py", line 945, in do_execute
    cursor.execute(statement, parameters)
  File "/home/lucasalvador/Reportes/CBAMECAPACITA/venv/lib/python3.12/site-packages/pymysql/cursors.py", line 153, in execute
    result = self._query(query)
             ^^^^^^^^^^^^^^^^^^
  File "/home/lucasalvador/Reportes/CBAMECAPACITA/venv/lib/python3.12/site-packages/pymysql/cursors.py", line 322, in _query
    conn.query(q)
  File "/home/lucasalvador/Reportes/CBAMECAPACITA/venv/lib/python3.12/site-packages/pymysql/connections.py", line 563, in query
    self._affected_rows = self._read_query_result(unbuffered=unbuffered)
                          ^^^^^^^^^^^^^^^^^^^^^^^^^^^^^^^^^^^^^^^^^^^^^^
  File "/home/lucasalvador/Reportes/CBAMECAPACITA/venv/lib/python3.12/site-packages/pymysql/connections.py", line 825, in _read_query_result
    result.read()
  File "/home/lucasalvador/Reportes/CBAMECAPACITA/venv/lib/python3.12/site-packages/pymysql/connections.py", line 1199, in read
    first_packet = self.connection._read_packet()
                   ^^^^^^^^^^^^^^^^^^^^^^^^^^^^^^
  File "/home/lucasalvador/Reportes/CBAMECAPACITA/venv/lib/python3.12/site-packages/pymysql/connections.py", line 775, in _read_packet
    packet.raise_for_error()
  File "/home/lucasalvador/Reportes/CBAMECAPACITA/venv/lib/python3.12/site-packages/pymysql/protocol.py", line 219, in raise_for_error
    err.raise_mysql_exception(self._data)
  File "/home/lucasalvador/Reportes/CBAMECAPACITA/venv/lib/python3.12/site-packages/pymysql/err.py", line 150, in raise_mysql_exception
    raise errorclass(errno, errval)
sqlalchemy.exc.DataError: (pymysql.err.DataError) (1406, "Data too long for column 'n_certificacion' at row 1")
[SQL: 
                                INSERT INTO T_EQUIVALENCIAS_CURSOS (n_curso, n_certificacion)
                                VALUES (%(curso)s, %(cert)s)
                            ]
[parameters: {'curso': 'Acabado de Madera', 'cert': 'AUXILIAR EN CONSTRUCCIONES - CONSTRUCCI√ìN EN BASE H√öMEDA'}]
(Background on this error at: https://sqlalche.me/e/20/9h9h)

2025-04-28 13:27:51,195 - INFO - Configuraci√≥n de Hugging Face cargada correctamente
2025-04-28 13:28:21,432 - INFO - Configuraci√≥n de Hugging Face cargada correctamente
2025-04-28 13:29:47,775 - INFO - Configuraci√≥n de Hugging Face cargada correctamente
2025-04-28 13:29:48,994 - INFO - Configuraci√≥n de Hugging Face cargada correctamente
2025-04-28 13:31:08,786 - INFO - Configuraci√≥n de Hugging Face cargada correctamente
2025-04-28 13:40:35,682 - INFO - Configuraci√≥n de Hugging Face cargada correctamente
2025-04-28 13:40:49,886 - ERROR - Error al guardar equivalencia: Traceback (most recent call last):
  File "/home/lucasalvador/Reportes/CBAMECAPACITA/venv/lib/python3.12/site-packages/sqlalchemy/engine/base.py", line 1964, in _exec_single_context
    self.dialect.do_execute(
  File "/home/lucasalvador/Reportes/CBAMECAPACITA/venv/lib/python3.12/site-packages/sqlalchemy/engine/default.py", line 945, in do_execute
    cursor.execute(statement, parameters)
  File "/home/lucasalvador/Reportes/CBAMECAPACITA/venv/lib/python3.12/site-packages/pymysql/cursors.py", line 153, in execute
    result = self._query(query)
             ^^^^^^^^^^^^^^^^^^
  File "/home/lucasalvador/Reportes/CBAMECAPACITA/venv/lib/python3.12/site-packages/pymysql/cursors.py", line 322, in _query
    conn.query(q)
  File "/home/lucasalvador/Reportes/CBAMECAPACITA/venv/lib/python3.12/site-packages/pymysql/connections.py", line 563, in query
    self._affected_rows = self._read_query_result(unbuffered=unbuffered)
                          ^^^^^^^^^^^^^^^^^^^^^^^^^^^^^^^^^^^^^^^^^^^^^^
  File "/home/lucasalvador/Reportes/CBAMECAPACITA/venv/lib/python3.12/site-packages/pymysql/connections.py", line 825, in _read_query_result
    result.read()
  File "/home/lucasalvador/Reportes/CBAMECAPACITA/venv/lib/python3.12/site-packages/pymysql/connections.py", line 1199, in read
    first_packet = self.connection._read_packet()
                   ^^^^^^^^^^^^^^^^^^^^^^^^^^^^^^
  File "/home/lucasalvador/Reportes/CBAMECAPACITA/venv/lib/python3.12/site-packages/pymysql/connections.py", line 775, in _read_packet
    packet.raise_for_error()
  File "/home/lucasalvador/Reportes/CBAMECAPACITA/venv/lib/python3.12/site-packages/pymysql/protocol.py", line 219, in raise_for_error
    err.raise_mysql_exception(self._data)
  File "/home/lucasalvador/Reportes/CBAMECAPACITA/venv/lib/python3.12/site-packages/pymysql/err.py", line 150, in raise_mysql_exception
    raise errorclass(errno, errval)
pymysql.err.IntegrityError: (1062, "Duplicate entry 'Acabado de Madera-AUXILIAR EN CONSTRUCCIONES - CONSTRUCCI√ìN ...' for key 'UC_Equivalencia'")

The above exception was the direct cause of the following exception:

Traceback (most recent call last):
  File "/home/lucasalvador/Reportes/CBAMECAPACITA/src/pages/comparar_cursos.py", line 156, in analizar_compatibilidad
    conn.execute(sql, {"curso": curso_historico, "cert": certificacion})
  File "/home/lucasalvador/Reportes/CBAMECAPACITA/venv/lib/python3.12/site-packages/sqlalchemy/engine/base.py", line 1416, in execute
    return meth(
           ^^^^^
  File "/home/lucasalvador/Reportes/CBAMECAPACITA/venv/lib/python3.12/site-packages/sqlalchemy/sql/elements.py", line 523, in _execute_on_connection
    return connection._execute_clauseelement(
           ^^^^^^^^^^^^^^^^^^^^^^^^^^^^^^^^^^
  File "/home/lucasalvador/Reportes/CBAMECAPACITA/venv/lib/python3.12/site-packages/sqlalchemy/engine/base.py", line 1638, in _execute_clauseelement
    ret = self._execute_context(
          ^^^^^^^^^^^^^^^^^^^^^^
  File "/home/lucasalvador/Reportes/CBAMECAPACITA/venv/lib/python3.12/site-packages/sqlalchemy/engine/base.py", line 1843, in _execute_context
    return self._exec_single_context(
           ^^^^^^^^^^^^^^^^^^^^^^^^^^
  File "/home/lucasalvador/Reportes/CBAMECAPACITA/venv/lib/python3.12/site-packages/sqlalchemy/engine/base.py", line 1983, in _exec_single_context
    self._handle_dbapi_exception(
  File "/home/lucasalvador/Reportes/CBAMECAPACITA/venv/lib/python3.12/site-packages/sqlalchemy/engine/base.py", line 2352, in _handle_dbapi_exception
    raise sqlalchemy_exception.with_traceback(exc_info[2]) from e
  File "/home/lucasalvador/Reportes/CBAMECAPACITA/venv/lib/python3.12/site-packages/sqlalchemy/engine/base.py", line 1964, in _exec_single_context
    self.dialect.do_execute(
  File "/home/lucasalvador/Reportes/CBAMECAPACITA/venv/lib/python3.12/site-packages/sqlalchemy/engine/default.py", line 945, in do_execute
    cursor.execute(statement, parameters)
  File "/home/lucasalvador/Reportes/CBAMECAPACITA/venv/lib/python3.12/site-packages/pymysql/cursors.py", line 153, in execute
    result = self._query(query)
             ^^^^^^^^^^^^^^^^^^
  File "/home/lucasalvador/Reportes/CBAMECAPACITA/venv/lib/python3.12/site-packages/pymysql/cursors.py", line 322, in _query
    conn.query(q)
  File "/home/lucasalvador/Reportes/CBAMECAPACITA/venv/lib/python3.12/site-packages/pymysql/connections.py", line 563, in query
    self._affected_rows = self._read_query_result(unbuffered=unbuffered)
                          ^^^^^^^^^^^^^^^^^^^^^^^^^^^^^^^^^^^^^^^^^^^^^^
  File "/home/lucasalvador/Reportes/CBAMECAPACITA/venv/lib/python3.12/site-packages/pymysql/connections.py", line 825, in _read_query_result
    result.read()
  File "/home/lucasalvador/Reportes/CBAMECAPACITA/venv/lib/python3.12/site-packages/pymysql/connections.py", line 1199, in read
    first_packet = self.connection._read_packet()
                   ^^^^^^^^^^^^^^^^^^^^^^^^^^^^^^
  File "/home/lucasalvador/Reportes/CBAMECAPACITA/venv/lib/python3.12/site-packages/pymysql/connections.py", line 775, in _read_packet
    packet.raise_for_error()
  File "/home/lucasalvador/Reportes/CBAMECAPACITA/venv/lib/python3.12/site-packages/pymysql/protocol.py", line 219, in raise_for_error
    err.raise_mysql_exception(self._data)
  File "/home/lucasalvador/Reportes/CBAMECAPACITA/venv/lib/python3.12/site-packages/pymysql/err.py", line 150, in raise_mysql_exception
    raise errorclass(errno, errval)
sqlalchemy.exc.IntegrityError: (pymysql.err.IntegrityError) (1062, "Duplicate entry 'Acabado de Madera-AUXILIAR EN CONSTRUCCIONES - CONSTRUCCI√ìN ...' for key 'UC_Equivalencia'")
[SQL: 
                                INSERT INTO T_EQUIVALENCIAS_CURSOS (n_curso, n_certificacion)
                                VALUES (%(curso)s, %(cert)s)
                            ]
[parameters: {'curso': 'Acabado de Madera', 'cert': 'AUXILIAR EN CONSTRUCCIONES - CONSTRUCCI√ìN EN BASE H√öMEDA'}]
(Background on this error at: https://sqlalche.me/e/20/gkpj)

2025-04-28 13:40:56,370 - INFO - Configuraci√≥n de Hugging Face cargada correctamente
2025-04-28 13:40:57,295 - INFO - Configuraci√≥n de Hugging Face cargada correctamente
2025-04-28 13:56:09,988 - INFO - Configuraci√≥n de Hugging Face cargada correctamente
2025-04-28 13:56:09,991 - INFO - Descargando archivo desde Hugging Face: Dir-Tecno/CBAMECAPACITA
2025-04-28 13:56:12,243 - INFO - Datos cargados exitosamente: 251288 registros
2025-04-28 14:55:22,998 - INFO - Configuraci√≥n de Hugging Face cargada correctamente
2025-04-28 14:55:23,001 - INFO - Descargando archivo desde Hugging Face: Dir-Tecno/CBAMECAPACITA
2025-04-28 14:55:25,708 - INFO - Datos cargados exitosamente: 251288 registros
2025-04-28 15:47:31,732 - INFO - Configuraci√≥n de Hugging Face cargada correctamente
2025-04-28 15:47:31,737 - INFO - Descargando archivo desde Hugging Face: Dir-Tecno/CBAMECAPACITA
2025-04-28 15:47:33,964 - INFO - Datos cargados exitosamente: 251288 registros
2025-04-28 15:48:04,878 - INFO - Configuraci√≥n de Hugging Face cargada correctamente
2025-04-28 15:54:02,015 - INFO - Configuraci√≥n de Hugging Face cargada correctamente
2025-04-28 15:55:51,249 - INFO - Configuraci√≥n de Hugging Face cargada correctamente
2025-04-28 15:58:00,896 - INFO - Configuraci√≥n de Hugging Face cargada correctamente
2025-04-28 15:58:12,530 - ERROR - Error al cargar equivalencias: Traceback (most recent call last):
  File "/home/lucasalvador/Reportes/CBAMECAPACITA/venv/lib/python3.12/site-packages/sqlalchemy/engine/base.py", line 1964, in _exec_single_context
    self.dialect.do_execute(
  File "/home/lucasalvador/Reportes/CBAMECAPACITA/venv/lib/python3.12/site-packages/sqlalchemy/engine/default.py", line 945, in do_execute
    cursor.execute(statement, parameters)
  File "/home/lucasalvador/Reportes/CBAMECAPACITA/venv/lib/python3.12/site-packages/pymysql/cursors.py", line 153, in execute
    result = self._query(query)
             ^^^^^^^^^^^^^^^^^^
  File "/home/lucasalvador/Reportes/CBAMECAPACITA/venv/lib/python3.12/site-packages/pymysql/cursors.py", line 322, in _query
    conn.query(q)
  File "/home/lucasalvador/Reportes/CBAMECAPACITA/venv/lib/python3.12/site-packages/pymysql/connections.py", line 563, in query
    self._affected_rows = self._read_query_result(unbuffered=unbuffered)
                          ^^^^^^^^^^^^^^^^^^^^^^^^^^^^^^^^^^^^^^^^^^^^^^
  File "/home/lucasalvador/Reportes/CBAMECAPACITA/venv/lib/python3.12/site-packages/pymysql/connections.py", line 825, in _read_query_result
    result.read()
  File "/home/lucasalvador/Reportes/CBAMECAPACITA/venv/lib/python3.12/site-packages/pymysql/connections.py", line 1199, in read
    first_packet = self.connection._read_packet()
                   ^^^^^^^^^^^^^^^^^^^^^^^^^^^^^^
  File "/home/lucasalvador/Reportes/CBAMECAPACITA/venv/lib/python3.12/site-packages/pymysql/connections.py", line 775, in _read_packet
    packet.raise_for_error()
  File "/home/lucasalvador/Reportes/CBAMECAPACITA/venv/lib/python3.12/site-packages/pymysql/protocol.py", line 219, in raise_for_error
    err.raise_mysql_exception(self._data)
  File "/home/lucasalvador/Reportes/CBAMECAPACITA/venv/lib/python3.12/site-packages/pymysql/err.py", line 150, in raise_mysql_exception
    raise errorclass(errno, errval)
pymysql.err.OperationalError: (1054, "Unknown column 'eq.estado' in 'WHERE'")

The above exception was the direct cause of the following exception:

Traceback (most recent call last):
  File "/home/lucasalvador/Reportes/CBAMECAPACITA/src/pages/comparar_cursos.py", line 204, in analizar_compatibilidad
    df_equivalencias = pd.read_sql(query, engine)
                       ^^^^^^^^^^^^^^^^^^^^^^^^^^
  File "/home/lucasalvador/Reportes/CBAMECAPACITA/venv/lib/python3.12/site-packages/pandas/io/sql.py", line 734, in read_sql
    return pandas_sql.read_query(
           ^^^^^^^^^^^^^^^^^^^^^^
  File "/home/lucasalvador/Reportes/CBAMECAPACITA/venv/lib/python3.12/site-packages/pandas/io/sql.py", line 1836, in read_query
    result = self.execute(sql, params)
             ^^^^^^^^^^^^^^^^^^^^^^^^^
  File "/home/lucasalvador/Reportes/CBAMECAPACITA/venv/lib/python3.12/site-packages/pandas/io/sql.py", line 1659, in execute
    return self.con.exec_driver_sql(sql, *args)
           ^^^^^^^^^^^^^^^^^^^^^^^^^^^^^^^^^^^^
  File "/home/lucasalvador/Reportes/CBAMECAPACITA/venv/lib/python3.12/site-packages/sqlalchemy/engine/base.py", line 1776, in exec_driver_sql
    ret = self._execute_context(
          ^^^^^^^^^^^^^^^^^^^^^^
  File "/home/lucasalvador/Reportes/CBAMECAPACITA/venv/lib/python3.12/site-packages/sqlalchemy/engine/base.py", line 1843, in _execute_context
    return self._exec_single_context(
           ^^^^^^^^^^^^^^^^^^^^^^^^^^
  File "/home/lucasalvador/Reportes/CBAMECAPACITA/venv/lib/python3.12/site-packages/sqlalchemy/engine/base.py", line 1983, in _exec_single_context
    self._handle_dbapi_exception(
  File "/home/lucasalvador/Reportes/CBAMECAPACITA/venv/lib/python3.12/site-packages/sqlalchemy/engine/base.py", line 2352, in _handle_dbapi_exception
    raise sqlalchemy_exception.with_traceback(exc_info[2]) from e
  File "/home/lucasalvador/Reportes/CBAMECAPACITA/venv/lib/python3.12/site-packages/sqlalchemy/engine/base.py", line 1964, in _exec_single_context
    self.dialect.do_execute(
  File "/home/lucasalvador/Reportes/CBAMECAPACITA/venv/lib/python3.12/site-packages/sqlalchemy/engine/default.py", line 945, in do_execute
    cursor.execute(statement, parameters)
  File "/home/lucasalvador/Reportes/CBAMECAPACITA/venv/lib/python3.12/site-packages/pymysql/cursors.py", line 153, in execute
    result = self._query(query)
             ^^^^^^^^^^^^^^^^^^
  File "/home/lucasalvador/Reportes/CBAMECAPACITA/venv/lib/python3.12/site-packages/pymysql/cursors.py", line 322, in _query
    conn.query(q)
  File "/home/lucasalvador/Reportes/CBAMECAPACITA/venv/lib/python3.12/site-packages/pymysql/connections.py", line 563, in query
    self._affected_rows = self._read_query_result(unbuffered=unbuffered)
                          ^^^^^^^^^^^^^^^^^^^^^^^^^^^^^^^^^^^^^^^^^^^^^^
  File "/home/lucasalvador/Reportes/CBAMECAPACITA/venv/lib/python3.12/site-packages/pymysql/connections.py", line 825, in _read_query_result
    result.read()
  File "/home/lucasalvador/Reportes/CBAMECAPACITA/venv/lib/python3.12/site-packages/pymysql/connections.py", line 1199, in read
    first_packet = self.connection._read_packet()
                   ^^^^^^^^^^^^^^^^^^^^^^^^^^^^^^
  File "/home/lucasalvador/Reportes/CBAMECAPACITA/venv/lib/python3.12/site-packages/pymysql/connections.py", line 775, in _read_packet
    packet.raise_for_error()
  File "/home/lucasalvador/Reportes/CBAMECAPACITA/venv/lib/python3.12/site-packages/pymysql/protocol.py", line 219, in raise_for_error
    err.raise_mysql_exception(self._data)
  File "/home/lucasalvador/Reportes/CBAMECAPACITA/venv/lib/python3.12/site-packages/pymysql/err.py", line 150, in raise_mysql_exception
    raise errorclass(errno, errval)
sqlalchemy.exc.OperationalError: (pymysql.err.OperationalError) (1054, "Unknown column 'eq.estado' in 'WHERE'")
[SQL: 
                        SELECT 
                            eq.id_equivalencia,
                            eq.n_curso as curso_historico,
                            eq.n_certificacion as certificacion_actual,
                            eq.fecha_creacion,
                            eq.usuario_creacion,
                            eq.observaciones
                        FROM T_EQUIVALENCIAS_CURSOS eq
                        WHERE eq.estado = TRUE
                        ORDER BY eq.fecha_creacion DESC
                    ]
(Background on this error at: https://sqlalche.me/e/20/e3q8)

2025-04-28 16:01:02,411 - INFO - Configuraci√≥n de Hugging Face cargada correctamente
2025-04-29 12:35:45,686 - INFO - Configuraci√≥n de Hugging Face cargada correctamente
2025-04-29 12:35:45,689 - INFO - Descargando archivo desde Hugging Face: Dir-Tecno/CBAMECAPACITA
2025-04-29 12:35:47,944 - INFO - Datos cargados exitosamente: 251288 registros
2025-04-29 12:35:48,982 - ERROR - Error en la aplicaci√≥n: Traceback (most recent call last):
  File "/home/lucasalvador/Reportes/CBAMECAPACITA/src/pages/comparar_cursos.py", line 240, in main
    st.set_page_config(
  File "/home/lucasalvador/Reportes/CBAMECAPACITA/venv/lib/python3.12/site-packages/streamlit/runtime/metrics_util.py", line 409, in wrapped_func
    result = non_optional_func(*args, **kwargs)
             ^^^^^^^^^^^^^^^^^^^^^^^^^^^^^^^^^^
  File "/home/lucasalvador/Reportes/CBAMECAPACITA/venv/lib/python3.12/site-packages/streamlit/commands/page_config.py", line 273, in set_page_config
    ctx.enqueue(msg)
  File "/home/lucasalvador/Reportes/CBAMECAPACITA/venv/lib/python3.12/site-packages/streamlit/runtime/scriptrunner_utils/script_run_context.py", line 180, in enqueue
    raise StreamlitSetPageConfigMustBeFirstCommandError()
streamlit.errors.StreamlitSetPageConfigMustBeFirstCommandError: `set_page_config()` can only be called once per app page, and must be called as the first Streamlit command in your script.

For more information refer to the [docs](https://docs.streamlit.io/develop/api-reference/configuration/st.set_page_config).

2025-04-29 12:36:00,629 - INFO - Configuraci√≥n de Hugging Face cargada correctamente
2025-04-29 12:36:01,550 - ERROR - Error en la aplicaci√≥n: Traceback (most recent call last):
  File "/home/lucasalvador/Reportes/CBAMECAPACITA/src/pages/comparar_cursos.py", line 240, in main
    st.set_page_config(
  File "/home/lucasalvador/Reportes/CBAMECAPACITA/venv/lib/python3.12/site-packages/streamlit/runtime/metrics_util.py", line 409, in wrapped_func
    result = non_optional_func(*args, **kwargs)
             ^^^^^^^^^^^^^^^^^^^^^^^^^^^^^^^^^^
  File "/home/lucasalvador/Reportes/CBAMECAPACITA/venv/lib/python3.12/site-packages/streamlit/commands/page_config.py", line 273, in set_page_config
    ctx.enqueue(msg)
  File "/home/lucasalvador/Reportes/CBAMECAPACITA/venv/lib/python3.12/site-packages/streamlit/runtime/scriptrunner_utils/script_run_context.py", line 180, in enqueue
    raise StreamlitSetPageConfigMustBeFirstCommandError()
streamlit.errors.StreamlitSetPageConfigMustBeFirstCommandError: `set_page_config()` can only be called once per app page, and must be called as the first Streamlit command in your script.

For more information refer to the [docs](https://docs.streamlit.io/develop/api-reference/configuration/st.set_page_config).

2025-04-29 12:36:17,336 - INFO - Configuraci√≥n de Hugging Face cargada correctamente
2025-04-29 12:36:17,670 - INFO - Configuraci√≥n de Hugging Face cargada correctamente
2025-04-29 12:36:19,290 - ERROR - Error en la aplicaci√≥n: Traceback (most recent call last):
  File "/home/lucasalvador/Reportes/CBAMECAPACITA/src/pages/comparar_cursos.py", line 240, in main
    st.set_page_config(
  File "/home/lucasalvador/Reportes/CBAMECAPACITA/venv/lib/python3.12/site-packages/streamlit/runtime/metrics_util.py", line 409, in wrapped_func
    result = non_optional_func(*args, **kwargs)
             ^^^^^^^^^^^^^^^^^^^^^^^^^^^^^^^^^^
  File "/home/lucasalvador/Reportes/CBAMECAPACITA/venv/lib/python3.12/site-packages/streamlit/commands/page_config.py", line 273, in set_page_config
    ctx.enqueue(msg)
  File "/home/lucasalvador/Reportes/CBAMECAPACITA/venv/lib/python3.12/site-packages/streamlit/runtime/scriptrunner_utils/script_run_context.py", line 180, in enqueue
    raise StreamlitSetPageConfigMustBeFirstCommandError()
streamlit.errors.StreamlitSetPageConfigMustBeFirstCommandError: `set_page_config()` can only be called once per app page, and must be called as the first Streamlit command in your script.

For more information refer to the [docs](https://docs.streamlit.io/develop/api-reference/configuration/st.set_page_config).

2025-04-29 12:36:19,432 - ERROR - Error en la aplicaci√≥n: Traceback (most recent call last):
  File "/home/lucasalvador/Reportes/CBAMECAPACITA/src/pages/comparar_cursos.py", line 240, in main
    st.set_page_config(
  File "/home/lucasalvador/Reportes/CBAMECAPACITA/venv/lib/python3.12/site-packages/streamlit/runtime/metrics_util.py", line 409, in wrapped_func
    result = non_optional_func(*args, **kwargs)
             ^^^^^^^^^^^^^^^^^^^^^^^^^^^^^^^^^^
  File "/home/lucasalvador/Reportes/CBAMECAPACITA/venv/lib/python3.12/site-packages/streamlit/commands/page_config.py", line 273, in set_page_config
    ctx.enqueue(msg)
  File "/home/lucasalvador/Reportes/CBAMECAPACITA/venv/lib/python3.12/site-packages/streamlit/runtime/scriptrunner_utils/script_run_context.py", line 180, in enqueue
    raise StreamlitSetPageConfigMustBeFirstCommandError()
streamlit.errors.StreamlitSetPageConfigMustBeFirstCommandError: `set_page_config()` can only be called once per app page, and must be called as the first Streamlit command in your script.

For more information refer to the [docs](https://docs.streamlit.io/develop/api-reference/configuration/st.set_page_config).

2025-04-29 12:37:39,536 - ERROR - Error en configuraci√≥n de p√°gina: `set_page_config()` can only be called once per app page, and must be called as the first Streamlit command in your script.

For more information refer to the [docs](https://docs.streamlit.io/develop/api-reference/configuration/st.set_page_config).
2025-04-29 12:37:39,540 - INFO - Configuraci√≥n de Hugging Face cargada correctamente
2025-04-29 12:37:40,759 - ERROR - Error en la aplicaci√≥n: Traceback (most recent call last):
  File "/home/lucasalvador/Reportes/CBAMECAPACITA/src/pages/comparar_cursos.py", line 300, in main
    st.set_page_config(
  File "/home/lucasalvador/Reportes/CBAMECAPACITA/venv/lib/python3.12/site-packages/streamlit/runtime/metrics_util.py", line 409, in wrapped_func
    result = non_optional_func(*args, **kwargs)
             ^^^^^^^^^^^^^^^^^^^^^^^^^^^^^^^^^^
  File "/home/lucasalvador/Reportes/CBAMECAPACITA/venv/lib/python3.12/site-packages/streamlit/commands/page_config.py", line 273, in set_page_config
    ctx.enqueue(msg)
  File "/home/lucasalvador/Reportes/CBAMECAPACITA/venv/lib/python3.12/site-packages/streamlit/runtime/scriptrunner_utils/script_run_context.py", line 180, in enqueue
    raise StreamlitSetPageConfigMustBeFirstCommandError()
streamlit.errors.StreamlitSetPageConfigMustBeFirstCommandError: `set_page_config()` can only be called once per app page, and must be called as the first Streamlit command in your script.

For more information refer to the [docs](https://docs.streamlit.io/develop/api-reference/configuration/st.set_page_config).

2025-04-29 12:37:51,958 - ERROR - Error en configuraci√≥n de p√°gina: `set_page_config()` can only be called once per app page, and must be called as the first Streamlit command in your script.

For more information refer to the [docs](https://docs.streamlit.io/develop/api-reference/configuration/st.set_page_config).
2025-04-29 12:37:51,966 - INFO - Configuraci√≥n de Hugging Face cargada correctamente
2025-04-29 12:37:52,884 - ERROR - Error en la aplicaci√≥n: Traceback (most recent call last):
  File "/home/lucasalvador/Reportes/CBAMECAPACITA/src/pages/comparar_cursos.py", line 288, in main
    st.set_page_config(
  File "/home/lucasalvador/Reportes/CBAMECAPACITA/venv/lib/python3.12/site-packages/streamlit/runtime/metrics_util.py", line 409, in wrapped_func
    result = non_optional_func(*args, **kwargs)
             ^^^^^^^^^^^^^^^^^^^^^^^^^^^^^^^^^^
  File "/home/lucasalvador/Reportes/CBAMECAPACITA/venv/lib/python3.12/site-packages/streamlit/commands/page_config.py", line 273, in set_page_config
    ctx.enqueue(msg)
  File "/home/lucasalvador/Reportes/CBAMECAPACITA/venv/lib/python3.12/site-packages/streamlit/runtime/scriptrunner_utils/script_run_context.py", line 180, in enqueue
    raise StreamlitSetPageConfigMustBeFirstCommandError()
streamlit.errors.StreamlitSetPageConfigMustBeFirstCommandError: `set_page_config()` can only be called once per app page, and must be called as the first Streamlit command in your script.

For more information refer to the [docs](https://docs.streamlit.io/develop/api-reference/configuration/st.set_page_config).

2025-04-29 12:38:56,298 - ERROR - Error en configuraci√≥n de p√°gina: `set_page_config()` can only be called once per app page, and must be called as the first Streamlit command in your script.

For more information refer to the [docs](https://docs.streamlit.io/develop/api-reference/configuration/st.set_page_config).
2025-04-29 12:38:56,302 - INFO - Configuraci√≥n de Hugging Face cargada correctamente
2025-04-29 12:39:07,640 - ERROR - Error en la aplicaci√≥n: NoneType: None

2025-04-29 12:39:29,881 - INFO - Configuraci√≥n de Hugging Face cargada correctamente
2025-04-29 12:39:30,177 - INFO - Configuraci√≥n de Hugging Face cargada correctamente
2025-04-29 12:44:03,912 - ERROR - Error en configuraci√≥n de p√°gina: `set_page_config()` can only be called once per app page, and must be called as the first Streamlit command in your script.

For more information refer to the [docs](https://docs.streamlit.io/develop/api-reference/configuration/st.set_page_config).
2025-04-29 12:44:03,917 - INFO - Configuraci√≥n de Hugging Face cargada correctamente
2025-04-29 12:47:07,435 - INFO - Configuraci√≥n de Hugging Face cargada correctamente
2025-04-29 12:47:08,920 - INFO - Configuraci√≥n de Hugging Face cargada correctamente
2025-04-29 12:47:25,251 - INFO - Configuraci√≥n de Hugging Face cargada correctamente
2025-04-29 12:47:49,984 - INFO - Configuraci√≥n de Hugging Face cargada correctamente
2025-04-29 12:47:51,667 - INFO - Configuraci√≥n de Hugging Face cargada correctamente
2025-04-29 12:48:05,134 - INFO - Configuraci√≥n de Hugging Face cargada correctamente
2025-04-29 14:59:27,749 - ERROR - Error en configuraci√≥n de p√°gina: `set_page_config()` can only be called once per app page, and must be called as the first Streamlit command in your script.

For more information refer to the [docs](https://docs.streamlit.io/develop/api-reference/configuration/st.set_page_config).
2025-04-29 14:59:27,752 - INFO - Configuraci√≥n de Hugging Face cargada correctamente
2025-04-29 14:59:27,754 - INFO - Descargando archivo desde Hugging Face: Dir-Tecno/CBAMECAPACITA
2025-04-29 14:59:30,927 - INFO - Datos cargados exitosamente: 251288 registros
2025-04-29 14:59:51,300 - INFO - Configuraci√≥n de Hugging Face cargada correctamente
2025-04-29 14:59:52,535 - INFO - Configuraci√≥n de Hugging Face cargada correctamente
2025-04-29 14:59:54,943 - INFO - Configuraci√≥n de Hugging Face cargada correctamente
2025-04-29 14:59:58,332 - INFO - Configuraci√≥n de Hugging Face cargada correctamente
2025-04-29 15:02:17,410 - INFO - Configuraci√≥n de Hugging Face cargada correctamente
2025-04-29 15:02:18,907 - INFO - Configuraci√≥n de Hugging Face cargada correctamente
2025-04-29 15:13:33,531 - ERROR - Error en configuraci√≥n de p√°gina: `set_page_config()` can only be called once per app page, and must be called as the first Streamlit command in your script.

For more information refer to the [docs](https://docs.streamlit.io/develop/api-reference/configuration/st.set_page_config).
2025-04-29 15:13:33,536 - INFO - Configuraci√≥n de Hugging Face cargada correctamente
2025-04-29 15:14:12,513 - INFO - Configuraci√≥n de Hugging Face cargada correctamente
2025-04-29 15:15:30,162 - INFO - Configuraci√≥n de Hugging Face cargada correctamente
2025-04-29 15:15:51,808 - INFO - Configuraci√≥n de Hugging Face cargada correctamente
2025-04-29 15:16:38,362 - ERROR - Error en configuraci√≥n de p√°gina: `set_page_config()` can only be called once per app page, and must be called as the first Streamlit command in your script.

For more information refer to the [docs](https://docs.streamlit.io/develop/api-reference/configuration/st.set_page_config).
2025-04-29 15:16:38,366 - INFO - Configuraci√≥n de Hugging Face cargada correctamente
2025-04-29 15:17:13,263 - INFO - Configuraci√≥n de Hugging Face cargada correctamente
2025-04-29 15:24:53,656 - ERROR - Error en configuraci√≥n de p√°gina: `set_page_config()` can only be called once per app page, and must be called as the first Streamlit command in your script.

For more information refer to the [docs](https://docs.streamlit.io/develop/api-reference/configuration/st.set_page_config).
2025-04-29 15:24:53,660 - INFO - Configuraci√≥n de Hugging Face cargada correctamente
2025-04-29 15:25:40,058 - INFO - Configuraci√≥n de Hugging Face cargada correctamente
2025-04-29 15:26:00,939 - INFO - Configuraci√≥n de Hugging Face cargada correctamente
2025-04-29 15:26:28,560 - INFO - Configuraci√≥n de Hugging Face cargada correctamente
2025-04-29 15:26:29,728 - INFO - Configuraci√≥n de Hugging Face cargada correctamente
2025-04-29 15:31:27,435 - ERROR - Error en configuraci√≥n de p√°gina: `set_page_config()` can only be called once per app page, and must be called as the first Streamlit command in your script.

For more information refer to the [docs](https://docs.streamlit.io/develop/api-reference/configuration/st.set_page_config).
2025-04-29 15:31:27,438 - INFO - Configuraci√≥n de Hugging Face cargada correctamente
2025-04-29 15:31:54,235 - INFO - Configuraci√≥n de Hugging Face cargada correctamente
2025-04-29 15:38:12,924 - ERROR - Error en configuraci√≥n de p√°gina: `set_page_config()` can only be called once per app page, and must be called as the first Streamlit command in your script.

For more information refer to the [docs](https://docs.streamlit.io/develop/api-reference/configuration/st.set_page_config).
2025-04-29 15:38:12,930 - INFO - Configuraci√≥n de Hugging Face cargada correctamente
2025-04-29 15:38:20,619 - ERROR - Error al cargar equivalencias: Traceback (most recent call last):
  File "/home/lucasalvador/Reportes/CBAMECAPACITA/src/pages/comparar_cursos.py", line 515, in mostrar_equivalencias_existentes
    "Acci√≥n": st.column_config.ButtonColumn(
              ^^^^^^^^^^^^^^^^^^^^^^^^^^^^^
AttributeError: module 'streamlit.column_config' has no attribute 'ButtonColumn'

2025-04-29 15:45:42,150 - ERROR - Error en configuraci√≥n de p√°gina: `set_page_config()` can only be called once per app page, and must be called as the first Streamlit command in your script.

For more information refer to the [docs](https://docs.streamlit.io/develop/api-reference/configuration/st.set_page_config).
2025-04-29 15:45:42,154 - INFO - Configuraci√≥n de Hugging Face cargada correctamente
2025-04-29 15:45:42,158 - INFO - Descargando archivo desde Hugging Face: Dir-Tecno/CBAMECAPACITA
2025-04-29 15:45:44,642 - INFO - Datos cargados exitosamente: 251288 registros
2025-04-29 15:45:52,481 - ERROR - Error al cargar equivalencias: Traceback (most recent call last):
  File "/home/lucasalvador/Reportes/CBAMECAPACITA/src/pages/comparar_cursos.py", line 515, in mostrar_equivalencias_existentes
    "Acci√≥n": st.column_config.ButtonColumn(
              ^^^^^^^^^^^^^^^^^^^^^^^^^^^^^
AttributeError: module 'streamlit.column_config' has no attribute 'ButtonColumn'. Did you mean: 'JsonColumn'?

2025-04-29 15:46:43,794 - ERROR - Error en configuraci√≥n de p√°gina: `set_page_config()` can only be called once per app page, and must be called as the first Streamlit command in your script.

For more information refer to the [docs](https://docs.streamlit.io/develop/api-reference/configuration/st.set_page_config).
2025-04-29 15:46:43,799 - INFO - Configuraci√≥n de Hugging Face cargada correctamente
2025-04-29 15:47:15,156 - INFO - Configuraci√≥n de Hugging Face cargada correctamente
2025-04-29 15:54:40,053 - INFO - Configuraci√≥n de Hugging Face cargada correctamente
2025-04-29 15:55:00,698 - INFO - Configuraci√≥n de Hugging Face cargada correctamente
2025-04-29 15:55:47,344 - INFO - Configuraci√≥n de Hugging Face cargada correctamente
2025-04-29 15:55:56,848 - INFO - Configuraci√≥n de Hugging Face cargada correctamente
2025-04-30 12:46:35,334 - ERROR - Error en configuraci√≥n de p√°gina: `set_page_config()` can only be called once per app page, and must be called as the first Streamlit command in your script.

For more information refer to the [docs](https://docs.streamlit.io/develop/api-reference/configuration/st.set_page_config).
2025-04-30 12:46:35,340 - INFO - Configuraci√≥n de Hugging Face cargada correctamente
2025-04-30 12:46:35,343 - INFO - Descargando archivo desde Hugging Face: Dir-Tecno/CBAMECAPACITA
2025-04-30 12:46:37,579 - INFO - Datos cargados exitosamente: 251288 registros
2025-04-30 12:52:45,368 - INFO - Configuraci√≥n de Hugging Face cargada correctamente
2025-04-30 12:53:20,189 - ERROR - Error en configuraci√≥n de p√°gina: `set_page_config()` can only be called once per app page, and must be called as the first Streamlit command in your script.

For more information refer to the [docs](https://docs.streamlit.io/develop/api-reference/configuration/st.set_page_config).
2025-04-30 12:53:20,192 - INFO - Configuraci√≥n de Hugging Face cargada correctamente
2025-04-30 12:53:43,517 - INFO - Configuraci√≥n de Hugging Face cargada correctamente
2025-04-30 12:53:44,988 - INFO - Configuraci√≥n de Hugging Face cargada correctamente
2025-04-30 12:53:58,139 - INFO - Configuraci√≥n de Hugging Face cargada correctamente
2025-04-30 12:54:10,715 - INFO - Configuraci√≥n de Hugging Face cargada correctamente
2025-04-30 12:54:20,040 - INFO - Configuraci√≥n de Hugging Face cargada correctamente
2025-04-30 13:15:48,734 - ERROR - Error en configuraci√≥n de p√°gina: `set_page_config()` can only be called once per app page, and must be called as the first Streamlit command in your script.

For more information refer to the [docs](https://docs.streamlit.io/develop/api-reference/configuration/st.set_page_config).
2025-04-30 13:15:48,740 - INFO - Configuraci√≥n de Hugging Face cargada correctamente
2025-04-30 13:16:59,542 - INFO - Configuraci√≥n de Hugging Face cargada correctamente
2025-04-30 13:17:00,533 - INFO - Configuraci√≥n de Hugging Face cargada correctamente
2025-04-30 13:17:01,232 - INFO - Configuraci√≥n de Hugging Face cargada correctamente
2025-04-30 13:19:10,443 - INFO - Configuraci√≥n de Hugging Face cargada correctamente
2025-04-30 13:20:09,079 - INFO - Configuraci√≥n de Hugging Face cargada correctamente
2025-04-30 13:20:45,410 - INFO - Configuraci√≥n de Hugging Face cargada correctamente
2025-04-30 13:20:57,661 - INFO - Configuraci√≥n de Hugging Face cargada correctamente
2025-04-30 13:21:13,880 - INFO - Configuraci√≥n de Hugging Face cargada correctamente
2025-04-30 13:21:28,701 - INFO - Configuraci√≥n de Hugging Face cargada correctamente
2025-04-30 13:21:45,752 - INFO - Configuraci√≥n de Hugging Face cargada correctamente
2025-04-30 13:26:05,074 - ERROR - Error en configuraci√≥n de p√°gina: `set_page_config()` can only be called once per app page, and must be called as the first Streamlit command in your script.

For more information refer to the [docs](https://docs.streamlit.io/develop/api-reference/configuration/st.set_page_config).
2025-04-30 13:26:05,087 - INFO - Configuraci√≥n de Hugging Face cargada correctamente
2025-04-30 13:26:20,061 - INFO - Configuraci√≥n de Hugging Face cargada correctamente
2025-04-30 13:26:46,742 - INFO - Configuraci√≥n de Hugging Face cargada correctamente
2025-04-30 13:26:58,633 - INFO - Configuraci√≥n de Hugging Face cargada correctamente
2025-04-30 13:29:34,950 - ERROR - Error en configuraci√≥n de p√°gina: `set_page_config()` can only be called once per app page, and must be called as the first Streamlit command in your script.

For more information refer to the [docs](https://docs.streamlit.io/develop/api-reference/configuration/st.set_page_config).
2025-04-30 13:29:34,953 - INFO - Configuraci√≥n de Hugging Face cargada correctamente
2025-04-30 13:29:39,981 - ERROR - Error general en la aplicaci√≥n: Traceback (most recent call last):
  File "/home/lucasalvador/Reportes/CBAMECAPACITA/app.py", line 459, in main
    comparar_cursos_main()
  File "/home/lucasalvador/Reportes/CBAMECAPACITA/src/pages/comparar_cursos.py", line 496, in main
    marcar_equivalencias(df_historico, df_certificaciones)
  File "/home/lucasalvador/Reportes/CBAMECAPACITA/src/pages/comparar_cursos.py", line 227, in marcar_equivalencias
    curso['N_CURSO'].unique(),
    ^^^^^
UnboundLocalError: cannot access local variable 'curso' where it is not associated with a value

2025-04-30 13:29:41,926 - ERROR - Error en configuraci√≥n de p√°gina: `set_page_config()` can only be called once per app page, and must be called as the first Streamlit command in your script.

For more information refer to the [docs](https://docs.streamlit.io/develop/api-reference/configuration/st.set_page_config).
2025-04-30 13:29:41,929 - INFO - Configuraci√≥n de Hugging Face cargada correctamente
2025-04-30 13:29:46,779 - ERROR - Error general en la aplicaci√≥n: Traceback (most recent call last):
  File "/home/lucasalvador/Reportes/CBAMECAPACITA/app.py", line 459, in main
    comparar_cursos_main()
  File "/home/lucasalvador/Reportes/CBAMECAPACITA/src/pages/comparar_cursos.py", line 495, in main
    marcar_equivalencias(df_historico, df_certificaciones)
  File "/home/lucasalvador/Reportes/CBAMECAPACITA/src/pages/comparar_cursos.py", line 227, in marcar_equivalencias
    curso['N_CURSO'].unique(),
    ^^^^^
UnboundLocalError: cannot access local variable 'curso' where it is not associated with a value

2025-04-30 13:30:13,263 - INFO - Configuraci√≥n de Hugging Face cargada correctamente
2025-04-30 13:31:58,631 - INFO - Configuraci√≥n de Hugging Face cargada correctamente
2025-04-30 13:32:03,575 - ERROR - Error general en la aplicaci√≥n: Traceback (most recent call last):
  File "/home/lucasalvador/Reportes/CBAMECAPACITA/app.py", line 459, in main
    comparar_cursos_main()
  File "/home/lucasalvador/Reportes/CBAMECAPACITA/src/pages/comparar_cursos.py", line 495, in main
    marcar_equivalencias(df_historico, df_certificaciones)
  File "/home/lucasalvador/Reportes/CBAMECAPACITA/src/pages/comparar_cursos.py", line 227, in marcar_equivalencias
    curso['N_CURSO'].unique(),
    ^^^^^
UnboundLocalError: cannot access local variable 'curso' where it is not associated with a value

2025-04-30 13:32:05,048 - INFO - Configuraci√≥n de Hugging Face cargada correctamente
2025-04-30 13:32:38,359 - ERROR - Error en configuraci√≥n de p√°gina: `set_page_config()` can only be called once per app page, and must be called as the first Streamlit command in your script.

For more information refer to the [docs](https://docs.streamlit.io/develop/api-reference/configuration/st.set_page_config).
2025-04-30 13:32:38,362 - INFO - Configuraci√≥n de Hugging Face cargada correctamente
2025-04-30 13:32:50,531 - INFO - Configuraci√≥n de Hugging Face cargada correctamente
2025-04-30 13:33:01,846 - INFO - Configuraci√≥n de Hugging Face cargada correctamente
2025-04-30 13:33:03,241 - INFO - Configuraci√≥n de Hugging Face cargada correctamente
2025-04-30 13:33:13,791 - INFO - Configuraci√≥n de Hugging Face cargada correctamente
2025-04-30 13:33:14,048 - INFO - Configuraci√≥n de Hugging Face cargada correctamente
2025-04-30 13:33:26,564 - INFO - Configuraci√≥n de Hugging Face cargada correctamente
2025-04-30 13:38:18,041 - ERROR - Error en configuraci√≥n de p√°gina: `set_page_config()` can only be called once per app page, and must be called as the first Streamlit command in your script.

For more information refer to the [docs](https://docs.streamlit.io/develop/api-reference/configuration/st.set_page_config).
2025-04-30 13:38:18,047 - INFO - Configuraci√≥n de Hugging Face cargada correctamente
2025-04-30 13:40:39,971 - INFO - Configuraci√≥n de Hugging Face cargada correctamente
2025-04-30 13:40:50,994 - INFO - Configuraci√≥n de Hugging Face cargada correctamente
2025-04-30 13:41:00,375 - INFO - Configuraci√≥n de Hugging Face cargada correctamente
2025-04-30 13:46:23,501 - INFO - Configuraci√≥n de Hugging Face cargada correctamente
2025-04-30 13:46:24,589 - INFO - Configuraci√≥n de Hugging Face cargada correctamente
2025-04-30 13:49:33,113 - ERROR - Error en configuraci√≥n de p√°gina: `set_page_config()` can only be called once per app page, and must be called as the first Streamlit command in your script.

For more information refer to the [docs](https://docs.streamlit.io/develop/api-reference/configuration/st.set_page_config).
2025-04-30 13:49:33,116 - INFO - Configuraci√≥n de Hugging Face cargada correctamente
2025-04-30 13:49:33,118 - INFO - Descargando archivo desde Hugging Face: Dir-Tecno/CBAMECAPACITA
2025-04-30 13:49:35,730 - INFO - Datos cargados exitosamente: 251288 registros
2025-04-30 13:49:50,682 - INFO - Configuraci√≥n de Hugging Face cargada correctamente
2025-04-30 13:50:02,693 - INFO - Configuraci√≥n de Hugging Face cargada correctamente
2025-04-30 13:53:46,775 - ERROR - Error en configuraci√≥n de p√°gina: `set_page_config()` can only be called once per app page, and must be called as the first Streamlit command in your script.

For more information refer to the [docs](https://docs.streamlit.io/develop/api-reference/configuration/st.set_page_config).
2025-04-30 13:53:46,779 - INFO - Configuraci√≥n de Hugging Face cargada correctamente
2025-04-30 13:54:37,280 - ERROR - Error en configuraci√≥n de p√°gina: `set_page_config()` can only be called once per app page, and must be called as the first Streamlit command in your script.

For more information refer to the [docs](https://docs.streamlit.io/develop/api-reference/configuration/st.set_page_config).
2025-04-30 13:54:37,284 - INFO - Configuraci√≥n de Hugging Face cargada correctamente
2025-04-30 13:55:25,300 - ERROR - Error en configuraci√≥n de p√°gina: `set_page_config()` can only be called once per app page, and must be called as the first Streamlit command in your script.

For more information refer to the [docs](https://docs.streamlit.io/develop/api-reference/configuration/st.set_page_config).
2025-04-30 13:55:25,303 - INFO - Configuraci√≥n de Hugging Face cargada correctamente
2025-04-30 13:55:35,620 - INFO - Configuraci√≥n de Hugging Face cargada correctamente
2025-04-30 13:55:44,208 - INFO - Configuraci√≥n de Hugging Face cargada correctamente
2025-05-05 12:27:31,202 - ERROR - Error en configuraci√≥n de p√°gina: `set_page_config()` can only be called once per app page, and must be called as the first Streamlit command in your script.

For more information refer to the [docs](https://docs.streamlit.io/develop/api-reference/configuration/st.set_page_config).
2025-05-05 12:27:31,207 - INFO - Configuraci√≥n de Hugging Face cargada correctamente
2025-05-05 12:27:31,210 - INFO - Descargando archivo desde Hugging Face: Dir-Tecno/CBAMECAPACITA
2025-05-05 12:27:33,586 - INFO - Datos cargados exitosamente: 251288 registros
2025-05-05 12:27:44,178 - INFO - Configuraci√≥n de Hugging Face cargada correctamente
2025-05-05 12:27:50,987 - INFO - Configuraci√≥n de Hugging Face cargada correctamente
2025-05-05 12:27:58,347 - INFO - Configuraci√≥n de Hugging Face cargada correctamente
2025-05-05 12:28:11,764 - INFO - Configuraci√≥n de Hugging Face cargada correctamente
2025-05-05 12:28:19,969 - ERROR - Error al eliminar equivalencia: Traceback (most recent call last):
  File "/home/lucasalvador/Reportes/CBAMECAPACITA/src/pages/comparar_cursos.py", line 797, in mostrar_equivalencias_existentes
    st.experimental_rerun()
    ^^^^^^^^^^^^^^^^^^^^^
AttributeError: module 'streamlit' has no attribute 'experimental_rerun'. Did you mean: 'experimental_user'?

2025-05-05 12:29:21,539 - ERROR - Error en configuraci√≥n de p√°gina: `set_page_config()` can only be called once per app page, and must be called as the first Streamlit command in your script.

For more information refer to the [docs](https://docs.streamlit.io/develop/api-reference/configuration/st.set_page_config).
2025-05-05 12:29:21,542 - INFO - Configuraci√≥n de Hugging Face cargada correctamente
2025-05-05 12:29:45,160 - INFO - Configuraci√≥n de Hugging Face cargada correctamente
2025-05-05 12:29:53,671 - INFO - Configuraci√≥n de Hugging Face cargada correctamente
2025-05-05 12:31:32,228 - ERROR - Error en configuraci√≥n de p√°gina: `set_page_config()` can only be called once per app page, and must be called as the first Streamlit command in your script.

For more information refer to the [docs](https://docs.streamlit.io/develop/api-reference/configuration/st.set_page_config).
2025-05-05 12:31:32,236 - INFO - Configuraci√≥n de Hugging Face cargada correctamente
2025-05-05 12:31:39,860 - ERROR - Error al mostrar equivalencias: Traceback (most recent call last):
  File "/home/lucasalvador/Reportes/CBAMECAPACITA/src/pages/comparar_cursos.py", line 766, in mostrar_equivalencias_existentes
    id_seleccionado = st.selectbox(
                      ^^^^^^^^^^^^^
  File "/home/lucasalvador/Reportes/CBAMECAPACITA/venv/lib/python3.12/site-packages/streamlit/runtime/metrics_util.py", line 410, in wrapped_func
    result = non_optional_func(*args, **kwargs)
             ^^^^^^^^^^^^^^^^^^^^^^^^^^^^^^^^^^
TypeError: SelectboxMixin.selectbox() missing 1 required positional argument: 'label'

2025-05-05 12:33:01,649 - ERROR - Error en configuraci√≥n de p√°gina: `set_page_config()` can only be called once per app page, and must be called as the first Streamlit command in your script.

For more information refer to the [docs](https://docs.streamlit.io/develop/api-reference/configuration/st.set_page_config).
2025-05-05 12:33:01,655 - INFO - Configuraci√≥n de Hugging Face cargada correctamente
2025-05-05 12:33:01,661 - INFO - Descargando archivo desde Hugging Face: Dir-Tecno/CBAMECAPACITA
2025-05-05 12:33:04,072 - INFO - Datos cargados exitosamente: 251288 registros
2025-05-05 12:33:29,356 - INFO - Configuraci√≥n de Hugging Face cargada correctamente
2025-05-05 12:34:03,352 - INFO - Configuraci√≥n de Hugging Face cargada correctamente
2025-05-05 12:34:11,843 - INFO - Configuraci√≥n de Hugging Face cargada correctamente
2025-05-05 12:34:24,849 - INFO - Configuraci√≥n de Hugging Face cargada correctamente
2025-05-05 12:34:34,188 - INFO - Configuraci√≥n de Hugging Face cargada correctamente
2025-05-05 12:34:52,083 - INFO - Configuraci√≥n de Hugging Face cargada correctamente
2025-05-05 12:35:00,549 - INFO - Configuraci√≥n de Hugging Face cargada correctamente
2025-05-05 12:44:51,306 - INFO - Configuraci√≥n de Hugging Face cargada correctamente
2025-05-05 14:14:13,852 - ERROR - Error en configuraci√≥n de p√°gina: `set_page_config()` can only be called once per app page, and must be called as the first Streamlit command in your script.

For more information refer to the [docs](https://docs.streamlit.io/develop/api-reference/configuration/st.set_page_config).
2025-05-05 14:14:13,865 - INFO - Configuraci√≥n de Hugging Face cargada correctamente
2025-05-05 14:14:13,870 - INFO - Descargando archivo desde Hugging Face: Dir-Tecno/CBAMECAPACITA
2025-05-05 14:14:18,118 - INFO - Datos cargados exitosamente: 251288 registros
2025-05-05 14:14:26,254 - INFO - Configuraci√≥n de Hugging Face cargada correctamente
2025-05-05 14:14:32,295 - INFO - Configuraci√≥n de Hugging Face cargada correctamente
2025-05-05 14:14:42,061 - INFO - Configuraci√≥n de Hugging Face cargada correctamente
2025-05-05 14:14:54,029 - INFO - Configuraci√≥n de Hugging Face cargada correctamente
2025-05-05 14:15:01,889 - INFO - Configuraci√≥n de Hugging Face cargada correctamente
2025-05-05 14:15:15,266 - INFO - Configuraci√≥n de Hugging Face cargada correctamente
2025-05-05 14:15:31,184 - INFO - Configuraci√≥n de Hugging Face cargada correctamente
2025-05-05 14:15:43,640 - INFO - Configuraci√≥n de Hugging Face cargada correctamente
2025-05-05 14:15:51,346 - ERROR - Error al eliminar equivalencia: Traceback (most recent call last):
  File "/home/lucasalvador/Reportes/CBAMECAPACITA/venv/lib/python3.12/site-packages/sqlalchemy/engine/base.py", line 1964, in _exec_single_context
    self.dialect.do_execute(
  File "/home/lucasalvador/Reportes/CBAMECAPACITA/venv/lib/python3.12/site-packages/sqlalchemy/engine/default.py", line 945, in do_execute
    cursor.execute(statement, parameters)
  File "/home/lucasalvador/Reportes/CBAMECAPACITA/venv/lib/python3.12/site-packages/pymysql/cursors.py", line 153, in execute
    result = self._query(query)
             ^^^^^^^^^^^^^^^^^^
  File "/home/lucasalvador/Reportes/CBAMECAPACITA/venv/lib/python3.12/site-packages/pymysql/cursors.py", line 322, in _query
    conn.query(q)
  File "/home/lucasalvador/Reportes/CBAMECAPACITA/venv/lib/python3.12/site-packages/pymysql/connections.py", line 563, in query
    self._affected_rows = self._read_query_result(unbuffered=unbuffered)
                          ^^^^^^^^^^^^^^^^^^^^^^^^^^^^^^^^^^^^^^^^^^^^^^
  File "/home/lucasalvador/Reportes/CBAMECAPACITA/venv/lib/python3.12/site-packages/pymysql/connections.py", line 825, in _read_query_result
    result.read()
  File "/home/lucasalvador/Reportes/CBAMECAPACITA/venv/lib/python3.12/site-packages/pymysql/connections.py", line 1199, in read
    first_packet = self.connection._read_packet()
                   ^^^^^^^^^^^^^^^^^^^^^^^^^^^^^^
  File "/home/lucasalvador/Reportes/CBAMECAPACITA/venv/lib/python3.12/site-packages/pymysql/connections.py", line 775, in _read_packet
    packet.raise_for_error()
  File "/home/lucasalvador/Reportes/CBAMECAPACITA/venv/lib/python3.12/site-packages/pymysql/protocol.py", line 219, in raise_for_error
    err.raise_mysql_exception(self._data)
  File "/home/lucasalvador/Reportes/CBAMECAPACITA/venv/lib/python3.12/site-packages/pymysql/err.py", line 150, in raise_mysql_exception
    raise errorclass(errno, errval)
pymysql.err.ProgrammingError: (1146, "Table 'CBAMECAPACITA.AUDITORIA_EQUIVALENCIAS' doesn't exist")

The above exception was the direct cause of the following exception:

Traceback (most recent call last):
  File "/home/lucasalvador/Reportes/CBAMECAPACITA/src/pages/comparar_cursos.py", line 803, in mostrar_equivalencias_existentes
    eliminar_equivalencia_con_auditoria(engine, id_seleccionado, usuario_actual)
  File "/home/lucasalvador/Reportes/CBAMECAPACITA/src/pages/comparar_cursos.py", line 197, in eliminar_equivalencia_con_auditoria
    conn.execute(
  File "/home/lucasalvador/Reportes/CBAMECAPACITA/venv/lib/python3.12/site-packages/sqlalchemy/engine/base.py", line 1416, in execute
    return meth(
           ^^^^^
  File "/home/lucasalvador/Reportes/CBAMECAPACITA/venv/lib/python3.12/site-packages/sqlalchemy/sql/elements.py", line 523, in _execute_on_connection
    return connection._execute_clauseelement(
           ^^^^^^^^^^^^^^^^^^^^^^^^^^^^^^^^^^
  File "/home/lucasalvador/Reportes/CBAMECAPACITA/venv/lib/python3.12/site-packages/sqlalchemy/engine/base.py", line 1638, in _execute_clauseelement
    ret = self._execute_context(
          ^^^^^^^^^^^^^^^^^^^^^^
  File "/home/lucasalvador/Reportes/CBAMECAPACITA/venv/lib/python3.12/site-packages/sqlalchemy/engine/base.py", line 1843, in _execute_context
    return self._exec_single_context(
           ^^^^^^^^^^^^^^^^^^^^^^^^^^
  File "/home/lucasalvador/Reportes/CBAMECAPACITA/venv/lib/python3.12/site-packages/sqlalchemy/engine/base.py", line 1983, in _exec_single_context
    self._handle_dbapi_exception(
  File "/home/lucasalvador/Reportes/CBAMECAPACITA/venv/lib/python3.12/site-packages/sqlalchemy/engine/base.py", line 2352, in _handle_dbapi_exception
    raise sqlalchemy_exception.with_traceback(exc_info[2]) from e
  File "/home/lucasalvador/Reportes/CBAMECAPACITA/venv/lib/python3.12/site-packages/sqlalchemy/engine/base.py", line 1964, in _exec_single_context
    self.dialect.do_execute(
  File "/home/lucasalvador/Reportes/CBAMECAPACITA/venv/lib/python3.12/site-packages/sqlalchemy/engine/default.py", line 945, in do_execute
    cursor.execute(statement, parameters)
  File "/home/lucasalvador/Reportes/CBAMECAPACITA/venv/lib/python3.12/site-packages/pymysql/cursors.py", line 153, in execute
    result = self._query(query)
             ^^^^^^^^^^^^^^^^^^
  File "/home/lucasalvador/Reportes/CBAMECAPACITA/venv/lib/python3.12/site-packages/pymysql/cursors.py", line 322, in _query
    conn.query(q)
  File "/home/lucasalvador/Reportes/CBAMECAPACITA/venv/lib/python3.12/site-packages/pymysql/connections.py", line 563, in query
    self._affected_rows = self._read_query_result(unbuffered=unbuffered)
                          ^^^^^^^^^^^^^^^^^^^^^^^^^^^^^^^^^^^^^^^^^^^^^^
  File "/home/lucasalvador/Reportes/CBAMECAPACITA/venv/lib/python3.12/site-packages/pymysql/connections.py", line 825, in _read_query_result
    result.read()
  File "/home/lucasalvador/Reportes/CBAMECAPACITA/venv/lib/python3.12/site-packages/pymysql/connections.py", line 1199, in read
    first_packet = self.connection._read_packet()
                   ^^^^^^^^^^^^^^^^^^^^^^^^^^^^^^
  File "/home/lucasalvador/Reportes/CBAMECAPACITA/venv/lib/python3.12/site-packages/pymysql/connections.py", line 775, in _read_packet
    packet.raise_for_error()
  File "/home/lucasalvador/Reportes/CBAMECAPACITA/venv/lib/python3.12/site-packages/pymysql/protocol.py", line 219, in raise_for_error
    err.raise_mysql_exception(self._data)
  File "/home/lucasalvador/Reportes/CBAMECAPACITA/venv/lib/python3.12/site-packages/pymysql/err.py", line 150, in raise_mysql_exception
    raise errorclass(errno, errval)
sqlalchemy.exc.ProgrammingError: (pymysql.err.ProgrammingError) (1146, "Table 'CBAMECAPACITA.AUDITORIA_EQUIVALENCIAS' doesn't exist")
[SQL: CALL eliminar_equivalencia_y_auditar(%(id_equivalencia)s, %(usuario)s)]
[parameters: {'id_equivalencia': 6, 'usuario': 'admin'}]
(Background on this error at: https://sqlalche.me/e/20/f405)

2025-05-05 14:20:11,025 - INFO - Configuraci√≥n de Hugging Face cargada correctamente
2025-05-05 14:20:19,403 - INFO - Configuraci√≥n de Hugging Face cargada correctamente
2025-05-05 14:20:42,793 - INFO - Configuraci√≥n de Hugging Face cargada correctamente
2025-05-05 14:20:54,451 - INFO - Configuraci√≥n de Hugging Face cargada correctamente
2025-05-05 14:21:02,788 - INFO - Configuraci√≥n de Hugging Face cargada correctamente
2025-05-05 14:21:16,662 - INFO - Configuraci√≥n de Hugging Face cargada correctamente
2025-05-05 14:21:26,745 - INFO - Configuraci√≥n de Hugging Face cargada correctamente
2025-05-05 14:21:34,427 - INFO - Configuraci√≥n de Hugging Face cargada correctamente
2025-05-05 14:23:10,658 - INFO - Configuraci√≥n de Hugging Face cargada correctamente
2025-05-05 14:25:44,383 - ERROR - Error en configuraci√≥n de p√°gina: `set_page_config()` can only be called once per app page, and must be called as the first Streamlit command in your script.

For more information refer to the [docs](https://docs.streamlit.io/develop/api-reference/configuration/st.set_page_config).
2025-05-05 14:25:44,387 - INFO - Configuraci√≥n de Hugging Face cargada correctamente
2025-05-05 14:34:04,897 - ERROR - Error en configuraci√≥n de p√°gina: `set_page_config()` can only be called once per app page, and must be called as the first Streamlit command in your script.

For more information refer to the [docs](https://docs.streamlit.io/develop/api-reference/configuration/st.set_page_config).
2025-05-05 14:34:04,900 - INFO - Configuraci√≥n de Hugging Face cargada correctamente
2025-05-05 14:34:16,612 - INFO - Configuraci√≥n de Hugging Face cargada correctamente
2025-05-05 14:34:25,955 - INFO - Configuraci√≥n de Hugging Face cargada correctamente
2025-05-05 14:34:33,801 - INFO - Configuraci√≥n de Hugging Face cargada correctamente
2025-05-05 14:34:44,142 - INFO - Configuraci√≥n de Hugging Face cargada correctamente
2025-05-05 14:34:50,591 - INFO - Configuraci√≥n de Hugging Face cargada correctamente
2025-05-05 14:34:59,181 - ERROR - Error al guardar equivalencias: Traceback (most recent call last):
  File "/home/lucasalvador/Reportes/CBAMECAPACITA/venv/lib/python3.12/site-packages/sqlalchemy/engine/base.py", line 1964, in _exec_single_context
    self.dialect.do_execute(
  File "/home/lucasalvador/Reportes/CBAMECAPACITA/venv/lib/python3.12/site-packages/sqlalchemy/engine/default.py", line 945, in do_execute
    cursor.execute(statement, parameters)
  File "/home/lucasalvador/Reportes/CBAMECAPACITA/venv/lib/python3.12/site-packages/pymysql/cursors.py", line 153, in execute
    result = self._query(query)
             ^^^^^^^^^^^^^^^^^^
  File "/home/lucasalvador/Reportes/CBAMECAPACITA/venv/lib/python3.12/site-packages/pymysql/cursors.py", line 322, in _query
    conn.query(q)
  File "/home/lucasalvador/Reportes/CBAMECAPACITA/venv/lib/python3.12/site-packages/pymysql/connections.py", line 563, in query
    self._affected_rows = self._read_query_result(unbuffered=unbuffered)
                          ^^^^^^^^^^^^^^^^^^^^^^^^^^^^^^^^^^^^^^^^^^^^^^
  File "/home/lucasalvador/Reportes/CBAMECAPACITA/venv/lib/python3.12/site-packages/pymysql/connections.py", line 825, in _read_query_result
    result.read()
  File "/home/lucasalvador/Reportes/CBAMECAPACITA/venv/lib/python3.12/site-packages/pymysql/connections.py", line 1199, in read
    first_packet = self.connection._read_packet()
                   ^^^^^^^^^^^^^^^^^^^^^^^^^^^^^^
  File "/home/lucasalvador/Reportes/CBAMECAPACITA/venv/lib/python3.12/site-packages/pymysql/connections.py", line 775, in _read_packet
    packet.raise_for_error()
  File "/home/lucasalvador/Reportes/CBAMECAPACITA/venv/lib/python3.12/site-packages/pymysql/protocol.py", line 219, in raise_for_error
    err.raise_mysql_exception(self._data)
  File "/home/lucasalvador/Reportes/CBAMECAPACITA/venv/lib/python3.12/site-packages/pymysql/err.py", line 150, in raise_mysql_exception
    raise errorclass(errno, errval)
pymysql.err.OperationalError: (1054, "Unknown column 'ID_CERTIFICACION' in 'WHERE'")

The above exception was the direct cause of the following exception:

Traceback (most recent call last):
  File "/home/lucasalvador/Reportes/CBAMECAPACITA/src/pages/comparar_cursos.py", line 657, in marcar_equivalencias
    result = crear_equivalencia_con_auditoria(
            ^^^^^^^^^^^^^^^^^^^^^^^^^^^^^^^^^
  File "/home/lucasalvador/Reportes/CBAMECAPACITA/src/pages/comparar_cursos.py", line 206, in crear_equivalencia_con_auditoria
    result = conn.execute(
             ^^^^^^^^^^^^^
  File "/home/lucasalvador/Reportes/CBAMECAPACITA/venv/lib/python3.12/site-packages/sqlalchemy/engine/base.py", line 1416, in execute
    return meth(
           ^^^^^
  File "/home/lucasalvador/Reportes/CBAMECAPACITA/venv/lib/python3.12/site-packages/sqlalchemy/sql/elements.py", line 523, in _execute_on_connection
    return connection._execute_clauseelement(
           ^^^^^^^^^^^^^^^^^^^^^^^^^^^^^^^^^^
  File "/home/lucasalvador/Reportes/CBAMECAPACITA/venv/lib/python3.12/site-packages/sqlalchemy/engine/base.py", line 1638, in _execute_clauseelement
    ret = self._execute_context(
          ^^^^^^^^^^^^^^^^^^^^^^
  File "/home/lucasalvador/Reportes/CBAMECAPACITA/venv/lib/python3.12/site-packages/sqlalchemy/engine/base.py", line 1843, in _execute_context
    return self._exec_single_context(
           ^^^^^^^^^^^^^^^^^^^^^^^^^^
  File "/home/lucasalvador/Reportes/CBAMECAPACITA/venv/lib/python3.12/site-packages/sqlalchemy/engine/base.py", line 1983, in _exec_single_context
    self._handle_dbapi_exception(
  File "/home/lucasalvador/Reportes/CBAMECAPACITA/venv/lib/python3.12/site-packages/sqlalchemy/engine/base.py", line 2352, in _handle_dbapi_exception
    raise sqlalchemy_exception.with_traceback(exc_info[2]) from e
  File "/home/lucasalvador/Reportes/CBAMECAPACITA/venv/lib/python3.12/site-packages/sqlalchemy/engine/base.py", line 1964, in _exec_single_context
    self.dialect.do_execute(
  File "/home/lucasalvador/Reportes/CBAMECAPACITA/venv/lib/python3.12/site-packages/sqlalchemy/engine/default.py", line 945, in do_execute
    cursor.execute(statement, parameters)
  File "/home/lucasalvador/Reportes/CBAMECAPACITA/venv/lib/python3.12/site-packages/pymysql/cursors.py", line 153, in execute
    result = self._query(query)
             ^^^^^^^^^^^^^^^^^^
  File "/home/lucasalvador/Reportes/CBAMECAPACITA/venv/lib/python3.12/site-packages/pymysql/cursors.py", line 322, in _query
    conn.query(q)
  File "/home/lucasalvador/Reportes/CBAMECAPACITA/venv/lib/python3.12/site-packages/pymysql/connections.py", line 563, in query
    self._affected_rows = self._read_query_result(unbuffered=unbuffered)
                          ^^^^^^^^^^^^^^^^^^^^^^^^^^^^^^^^^^^^^^^^^^^^^^
  File "/home/lucasalvador/Reportes/CBAMECAPACITA/venv/lib/python3.12/site-packages/pymysql/connections.py", line 825, in _read_query_result
    result.read()
  File "/home/lucasalvador/Reportes/CBAMECAPACITA/venv/lib/python3.12/site-packages/pymysql/connections.py", line 1199, in read
    first_packet = self.connection._read_packet()
                   ^^^^^^^^^^^^^^^^^^^^^^^^^^^^^^
  File "/home/lucasalvador/Reportes/CBAMECAPACITA/venv/lib/python3.12/site-packages/pymysql/connections.py", line 775, in _read_packet
    packet.raise_for_error()
  File "/home/lucasalvador/Reportes/CBAMECAPACITA/venv/lib/python3.12/site-packages/pymysql/protocol.py", line 219, in raise_for_error
    err.raise_mysql_exception(self._data)
  File "/home/lucasalvador/Reportes/CBAMECAPACITA/venv/lib/python3.12/site-packages/pymysql/err.py", line 150, in raise_mysql_exception
    raise errorclass(errno, errval)
sqlalchemy.exc.OperationalError: (pymysql.err.OperationalError) (1054, "Unknown column 'ID_CERTIFICACION' in 'WHERE'")
[SQL: CALL insertar_equivalencia_y_auditar(%(id_curso)s, %(n_curso)s, %(id_certificacion)s, %(n_certificacion)s, %(observaciones)s, %(usuario)s)]
[parameters: {'id_curso': 308, 'n_curso': 'Alfarer√≠a', 'id_certificacion': 1844.0, 'n_certificacion': 'ALFARER√çA - ALFARER√çA', 'observaciones': 'Equivalencia directa', 'usuario': 'admin'}]
(Background on this error at: https://sqlalche.me/e/20/e3q8)

2025-05-05 14:40:16,774 - INFO - Configuraci√≥n de Hugging Face cargada correctamente
2025-05-05 14:40:25,587 - ERROR - Error al guardar equivalencias: Traceback (most recent call last):
  File "/home/lucasalvador/Reportes/CBAMECAPACITA/venv/lib/python3.12/site-packages/sqlalchemy/engine/base.py", line 1964, in _exec_single_context
    self.dialect.do_execute(
  File "/home/lucasalvador/Reportes/CBAMECAPACITA/venv/lib/python3.12/site-packages/sqlalchemy/engine/default.py", line 945, in do_execute
    cursor.execute(statement, parameters)
  File "/home/lucasalvador/Reportes/CBAMECAPACITA/venv/lib/python3.12/site-packages/pymysql/cursors.py", line 153, in execute
    result = self._query(query)
             ^^^^^^^^^^^^^^^^^^
  File "/home/lucasalvador/Reportes/CBAMECAPACITA/venv/lib/python3.12/site-packages/pymysql/cursors.py", line 322, in _query
    conn.query(q)
  File "/home/lucasalvador/Reportes/CBAMECAPACITA/venv/lib/python3.12/site-packages/pymysql/connections.py", line 563, in query
    self._affected_rows = self._read_query_result(unbuffered=unbuffered)
                          ^^^^^^^^^^^^^^^^^^^^^^^^^^^^^^^^^^^^^^^^^^^^^^
  File "/home/lucasalvador/Reportes/CBAMECAPACITA/venv/lib/python3.12/site-packages/pymysql/connections.py", line 825, in _read_query_result
    result.read()
  File "/home/lucasalvador/Reportes/CBAMECAPACITA/venv/lib/python3.12/site-packages/pymysql/connections.py", line 1199, in read
    first_packet = self.connection._read_packet()
                   ^^^^^^^^^^^^^^^^^^^^^^^^^^^^^^
  File "/home/lucasalvador/Reportes/CBAMECAPACITA/venv/lib/python3.12/site-packages/pymysql/connections.py", line 775, in _read_packet
    packet.raise_for_error()
  File "/home/lucasalvador/Reportes/CBAMECAPACITA/venv/lib/python3.12/site-packages/pymysql/protocol.py", line 219, in raise_for_error
    err.raise_mysql_exception(self._data)
  File "/home/lucasalvador/Reportes/CBAMECAPACITA/venv/lib/python3.12/site-packages/pymysql/err.py", line 150, in raise_mysql_exception
    raise errorclass(errno, errval)
pymysql.err.OperationalError: (1305, 'PROCEDURE CBAMECAPACITA.insertar_equivalencia_y_auditar does not exist')

The above exception was the direct cause of the following exception:

Traceback (most recent call last):
  File "/home/lucasalvador/Reportes/CBAMECAPACITA/src/pages/comparar_cursos.py", line 657, in marcar_equivalencias
    result = crear_equivalencia_con_auditoria(
            ^^^^^^^^^^^^^^^^^^^^^^^^^^^^^^^^^
  File "/home/lucasalvador/Reportes/CBAMECAPACITA/src/pages/comparar_cursos.py", line 206, in crear_equivalencia_con_auditoria
    result = conn.execute(
             ^^^^^^^^^^^^^
  File "/home/lucasalvador/Reportes/CBAMECAPACITA/venv/lib/python3.12/site-packages/sqlalchemy/engine/base.py", line 1416, in execute
    return meth(
           ^^^^^
  File "/home/lucasalvador/Reportes/CBAMECAPACITA/venv/lib/python3.12/site-packages/sqlalchemy/sql/elements.py", line 523, in _execute_on_connection
    return connection._execute_clauseelement(
           ^^^^^^^^^^^^^^^^^^^^^^^^^^^^^^^^^^
  File "/home/lucasalvador/Reportes/CBAMECAPACITA/venv/lib/python3.12/site-packages/sqlalchemy/engine/base.py", line 1638, in _execute_clauseelement
    ret = self._execute_context(
          ^^^^^^^^^^^^^^^^^^^^^^
  File "/home/lucasalvador/Reportes/CBAMECAPACITA/venv/lib/python3.12/site-packages/sqlalchemy/engine/base.py", line 1843, in _execute_context
    return self._exec_single_context(
           ^^^^^^^^^^^^^^^^^^^^^^^^^^
  File "/home/lucasalvador/Reportes/CBAMECAPACITA/venv/lib/python3.12/site-packages/sqlalchemy/engine/base.py", line 1983, in _exec_single_context
    self._handle_dbapi_exception(
  File "/home/lucasalvador/Reportes/CBAMECAPACITA/venv/lib/python3.12/site-packages/sqlalchemy/engine/base.py", line 2352, in _handle_dbapi_exception
    raise sqlalchemy_exception.with_traceback(exc_info[2]) from e
  File "/home/lucasalvador/Reportes/CBAMECAPACITA/venv/lib/python3.12/site-packages/sqlalchemy/engine/base.py", line 1964, in _exec_single_context
    self.dialect.do_execute(
  File "/home/lucasalvador/Reportes/CBAMECAPACITA/venv/lib/python3.12/site-packages/sqlalchemy/engine/default.py", line 945, in do_execute
    cursor.execute(statement, parameters)
  File "/home/lucasalvador/Reportes/CBAMECAPACITA/venv/lib/python3.12/site-packages/pymysql/cursors.py", line 153, in execute
    result = self._query(query)
             ^^^^^^^^^^^^^^^^^^
  File "/home/lucasalvador/Reportes/CBAMECAPACITA/venv/lib/python3.12/site-packages/pymysql/cursors.py", line 322, in _query
    conn.query(q)
  File "/home/lucasalvador/Reportes/CBAMECAPACITA/venv/lib/python3.12/site-packages/pymysql/connections.py", line 563, in query
    self._affected_rows = self._read_query_result(unbuffered=unbuffered)
                          ^^^^^^^^^^^^^^^^^^^^^^^^^^^^^^^^^^^^^^^^^^^^^^
  File "/home/lucasalvador/Reportes/CBAMECAPACITA/venv/lib/python3.12/site-packages/pymysql/connections.py", line 825, in _read_query_result
    result.read()
  File "/home/lucasalvador/Reportes/CBAMECAPACITA/venv/lib/python3.12/site-packages/pymysql/connections.py", line 1199, in read
    first_packet = self.connection._read_packet()
                   ^^^^^^^^^^^^^^^^^^^^^^^^^^^^^^
  File "/home/lucasalvador/Reportes/CBAMECAPACITA/venv/lib/python3.12/site-packages/pymysql/connections.py", line 775, in _read_packet
    packet.raise_for_error()
  File "/home/lucasalvador/Reportes/CBAMECAPACITA/venv/lib/python3.12/site-packages/pymysql/protocol.py", line 219, in raise_for_error
    err.raise_mysql_exception(self._data)
  File "/home/lucasalvador/Reportes/CBAMECAPACITA/venv/lib/python3.12/site-packages/pymysql/err.py", line 150, in raise_mysql_exception
    raise errorclass(errno, errval)
sqlalchemy.exc.OperationalError: (pymysql.err.OperationalError) (1305, 'PROCEDURE CBAMECAPACITA.insertar_equivalencia_y_auditar does not exist')
[SQL: CALL insertar_equivalencia_y_auditar(%(id_curso)s, %(n_curso)s, %(id_certificacion)s, %(n_certificacion)s, %(observaciones)s, %(usuario)s)]
[parameters: {'id_curso': 308, 'n_curso': 'Alfarer√≠a', 'id_certificacion': 1844.0, 'n_certificacion': 'ALFARER√çA - ALFARER√çA', 'observaciones': 'Equivalencia directa', 'usuario': 'admin'}]
(Background on this error at: https://sqlalche.me/e/20/e3q8)

2025-05-05 14:42:31,616 - ERROR - Error en configuraci√≥n de p√°gina: `set_page_config()` can only be called once per app page, and must be called as the first Streamlit command in your script.

For more information refer to the [docs](https://docs.streamlit.io/develop/api-reference/configuration/st.set_page_config).
2025-05-05 14:42:31,619 - INFO - Configuraci√≥n de Hugging Face cargada correctamente
2025-05-05 14:42:39,048 - INFO - Configuraci√≥n de Hugging Face cargada correctamente
2025-05-05 14:42:47,800 - ERROR - Error al guardar equivalencias: Traceback (most recent call last):
  File "/home/lucasalvador/Reportes/CBAMECAPACITA/venv/lib/python3.12/site-packages/sqlalchemy/engine/base.py", line 1964, in _exec_single_context
    self.dialect.do_execute(
  File "/home/lucasalvador/Reportes/CBAMECAPACITA/venv/lib/python3.12/site-packages/sqlalchemy/engine/default.py", line 945, in do_execute
    cursor.execute(statement, parameters)
  File "/home/lucasalvador/Reportes/CBAMECAPACITA/venv/lib/python3.12/site-packages/pymysql/cursors.py", line 153, in execute
    result = self._query(query)
             ^^^^^^^^^^^^^^^^^^
  File "/home/lucasalvador/Reportes/CBAMECAPACITA/venv/lib/python3.12/site-packages/pymysql/cursors.py", line 322, in _query
    conn.query(q)
  File "/home/lucasalvador/Reportes/CBAMECAPACITA/venv/lib/python3.12/site-packages/pymysql/connections.py", line 563, in query
    self._affected_rows = self._read_query_result(unbuffered=unbuffered)
                          ^^^^^^^^^^^^^^^^^^^^^^^^^^^^^^^^^^^^^^^^^^^^^^
  File "/home/lucasalvador/Reportes/CBAMECAPACITA/venv/lib/python3.12/site-packages/pymysql/connections.py", line 825, in _read_query_result
    result.read()
  File "/home/lucasalvador/Reportes/CBAMECAPACITA/venv/lib/python3.12/site-packages/pymysql/connections.py", line 1199, in read
    first_packet = self.connection._read_packet()
                   ^^^^^^^^^^^^^^^^^^^^^^^^^^^^^^
  File "/home/lucasalvador/Reportes/CBAMECAPACITA/venv/lib/python3.12/site-packages/pymysql/connections.py", line 775, in _read_packet
    packet.raise_for_error()
  File "/home/lucasalvador/Reportes/CBAMECAPACITA/venv/lib/python3.12/site-packages/pymysql/protocol.py", line 219, in raise_for_error
    err.raise_mysql_exception(self._data)
  File "/home/lucasalvador/Reportes/CBAMECAPACITA/venv/lib/python3.12/site-packages/pymysql/err.py", line 150, in raise_mysql_exception
    raise errorclass(errno, errval)
pymysql.err.OperationalError: (1054, "Unknown column 'DETALLES' in 'INSERT INTO'")

The above exception was the direct cause of the following exception:

Traceback (most recent call last):
  File "/home/lucasalvador/Reportes/CBAMECAPACITA/src/pages/comparar_cursos.py", line 657, in marcar_equivalencias
    result = crear_equivalencia_con_auditoria(
            ^^^^^^^^^^^^^^^^^^^^^^^^^^^^^^^^^
  File "/home/lucasalvador/Reportes/CBAMECAPACITA/src/pages/comparar_cursos.py", line 206, in crear_equivalencia_con_auditoria
    result = conn.execute(
             ^^^^^^^^^^^^^
  File "/home/lucasalvador/Reportes/CBAMECAPACITA/venv/lib/python3.12/site-packages/sqlalchemy/engine/base.py", line 1416, in execute
    return meth(
           ^^^^^
  File "/home/lucasalvador/Reportes/CBAMECAPACITA/venv/lib/python3.12/site-packages/sqlalchemy/sql/elements.py", line 523, in _execute_on_connection
    return connection._execute_clauseelement(
           ^^^^^^^^^^^^^^^^^^^^^^^^^^^^^^^^^^
  File "/home/lucasalvador/Reportes/CBAMECAPACITA/venv/lib/python3.12/site-packages/sqlalchemy/engine/base.py", line 1638, in _execute_clauseelement
    ret = self._execute_context(
          ^^^^^^^^^^^^^^^^^^^^^^
  File "/home/lucasalvador/Reportes/CBAMECAPACITA/venv/lib/python3.12/site-packages/sqlalchemy/engine/base.py", line 1843, in _execute_context
    return self._exec_single_context(
           ^^^^^^^^^^^^^^^^^^^^^^^^^^
  File "/home/lucasalvador/Reportes/CBAMECAPACITA/venv/lib/python3.12/site-packages/sqlalchemy/engine/base.py", line 1983, in _exec_single_context
    self._handle_dbapi_exception(
  File "/home/lucasalvador/Reportes/CBAMECAPACITA/venv/lib/python3.12/site-packages/sqlalchemy/engine/base.py", line 2352, in _handle_dbapi_exception
    raise sqlalchemy_exception.with_traceback(exc_info[2]) from e
  File "/home/lucasalvador/Reportes/CBAMECAPACITA/venv/lib/python3.12/site-packages/sqlalchemy/engine/base.py", line 1964, in _exec_single_context
    self.dialect.do_execute(
  File "/home/lucasalvador/Reportes/CBAMECAPACITA/venv/lib/python3.12/site-packages/sqlalchemy/engine/default.py", line 945, in do_execute
    cursor.execute(statement, parameters)
  File "/home/lucasalvador/Reportes/CBAMECAPACITA/venv/lib/python3.12/site-packages/pymysql/cursors.py", line 153, in execute
    result = self._query(query)
             ^^^^^^^^^^^^^^^^^^
  File "/home/lucasalvador/Reportes/CBAMECAPACITA/venv/lib/python3.12/site-packages/pymysql/cursors.py", line 322, in _query
    conn.query(q)
  File "/home/lucasalvador/Reportes/CBAMECAPACITA/venv/lib/python3.12/site-packages/pymysql/connections.py", line 563, in query
    self._affected_rows = self._read_query_result(unbuffered=unbuffered)
                          ^^^^^^^^^^^^^^^^^^^^^^^^^^^^^^^^^^^^^^^^^^^^^^
  File "/home/lucasalvador/Reportes/CBAMECAPACITA/venv/lib/python3.12/site-packages/pymysql/connections.py", line 825, in _read_query_result
    result.read()
  File "/home/lucasalvador/Reportes/CBAMECAPACITA/venv/lib/python3.12/site-packages/pymysql/connections.py", line 1199, in read
    first_packet = self.connection._read_packet()
                   ^^^^^^^^^^^^^^^^^^^^^^^^^^^^^^
  File "/home/lucasalvador/Reportes/CBAMECAPACITA/venv/lib/python3.12/site-packages/pymysql/connections.py", line 775, in _read_packet
    packet.raise_for_error()
  File "/home/lucasalvador/Reportes/CBAMECAPACITA/venv/lib/python3.12/site-packages/pymysql/protocol.py", line 219, in raise_for_error
    err.raise_mysql_exception(self._data)
  File "/home/lucasalvador/Reportes/CBAMECAPACITA/venv/lib/python3.12/site-packages/pymysql/err.py", line 150, in raise_mysql_exception
    raise errorclass(errno, errval)
sqlalchemy.exc.OperationalError: (pymysql.err.OperationalError) (1054, "Unknown column 'DETALLES' in 'INSERT INTO'")
[SQL: CALL FN_INSERTA_EQUIVALENCIA_AUDITA (%(id_curso)s, %(n_curso)s, %(id_certificacion)s, %(n_certificacion)s, %(observaciones)s, %(usuario)s)]
[parameters: {'id_curso': 308, 'n_curso': 'Alfarer√≠a', 'id_certificacion': 1844.0, 'n_certificacion': 'ALFARER√çA - ALFARER√çA', 'observaciones': 'Equivalencia directa', 'usuario': 'admin'}]
(Background on this error at: https://sqlalche.me/e/20/e3q8)

2025-05-05 14:46:58,362 - INFO - Configuraci√≥n de Hugging Face cargada correctamente
2025-05-05 14:47:10,906 - INFO - Configuraci√≥n de Hugging Face cargada correctamente
2025-05-05 14:47:21,206 - INFO - Configuraci√≥n de Hugging Face cargada correctamente
2025-05-05 14:47:30,499 - INFO - Configuraci√≥n de Hugging Face cargada correctamente
2025-05-05 14:59:43,541 - INFO - Configuraci√≥n de Hugging Face cargada correctamente
2025-05-05 15:09:50,424 - INFO - Configuraci√≥n de Hugging Face cargada correctamente
2025-05-05 15:14:06,281 - INFO - Configuraci√≥n de Hugging Face cargada correctamente
2025-05-05 15:15:40,892 - INFO - Configuraci√≥n de Hugging Face cargada correctamente
2025-05-05 15:18:28,258 - INFO - Configuraci√≥n de Hugging Face cargada correctamente
2025-05-05 15:18:28,260 - INFO - Descargando archivo desde Hugging Face: Dir-Tecno/CBAMECAPACITA
2025-05-05 15:18:31,848 - INFO - Datos cargados exitosamente: 251288 registros
2025-05-05 15:24:08,676 - INFO - Configuraci√≥n de Hugging Face cargada correctamente
2025-05-05 15:24:10,057 - INFO - Configuraci√≥n de Hugging Face cargada correctamente
2025-05-05 15:24:20,006 - INFO - Configuraci√≥n de Hugging Face cargada correctamente
2025-05-05 15:24:23,188 - INFO - Configuraci√≥n de Hugging Face cargada correctamente
2025-05-05 15:24:24,174 - INFO - Configuraci√≥n de Hugging Face cargada correctamente
2025-05-05 15:24:24,925 - INFO - Configuraci√≥n de Hugging Face cargada correctamente
2025-05-05 15:24:35,561 - INFO - Configuraci√≥n de Hugging Face cargada correctamente
2025-05-05 15:25:23,563 - INFO - Configuraci√≥n de Hugging Face cargada correctamente
2025-05-05 15:25:47,283 - INFO - Configuraci√≥n de Hugging Face cargada correctamente
2025-05-05 15:25:55,322 - INFO - Configuraci√≥n de Hugging Face cargada correctamente
2025-05-05 15:28:59,295 - INFO - Configuraci√≥n de Hugging Face cargada correctamente
2025-05-05 15:29:08,750 - INFO - Configuraci√≥n de Hugging Face cargada correctamente
2025-05-05 15:29:27,399 - ERROR - Error en configuraci√≥n de p√°gina: `set_page_config()` can only be called once per app page, and must be called as the first Streamlit command in your script.

For more information refer to the [docs](https://docs.streamlit.io/develop/api-reference/configuration/st.set_page_config).
2025-05-05 15:29:27,401 - INFO - Configuraci√≥n de Hugging Face cargada correctamente
